Workbook

Sheet Resumen
A1: Consolidated Income | C1: DIA | D1: =COUNT(C7:C37) -> 0
A3: =+'Biyemas S.A.'!A3 -> Reporte Flash Agosto 26
D4: SLOTS | L4: ELECTRONIC ROULLETTE - ON LINE | T4: Win | U4: Total | V4: MAQUINA POKER | AD4: On line | AE4: Win | AG4: BINGO | AL4: FOOD & BEVERAGE | AN4: PARKING | AQ4: EGA | AY4: Positions | BA4: Customers | BC4: Vehicles | BE4: Revenues vs. Budget (w/seasonality) | BJ4: Revenues
D5: ON LINE | O5: on line | P5: % win/ | Q5: % win/ | T5: (Slot + RE) | U5: electronic | V5: ON LINE | AD5: Electronic | AE5: Financial | AF5: Difference | AG5: nº | AI5: Net | AK5: Total | AV5: TOTAL NET | AY5: on line | AZ5: vs. Budget | BA5: Budget | BB5: Deviation | BC5: Budget | BD5: Desviation | BE5: Total | BF5: Electronic | BG5: Bingo | BH5: F&B | BI5: Parking | BJ5: Total | BK5: Electronic | BL5: Bingo | BM5: F&B | BN5: Parking
A6: Day | B6: Fecha | C6: Custom. | D6: Units | E6: Coin in | F6: Drop | G6: Win | H6: coin in | I6: Drop | J6: /Cust. | K6: /Units. | L6: Seats | M6: Coin in | N6: Drop | O6: Win | P6: coin in | Q6: Drop | R6: /Cust. | S6: /Seat | T6: / Stand | U6: positions | V6: Units | W6: Coin in | X6: Drop | Y6: Win | Z6: coin in | AA6: Drop | AB6: /Cust. | AC6: /Units. | AD6: Win | AE6: Win | AG6: Cards | AH6: Sales | AI6: win | AJ6: /Cust. | AK6: Gaming | AL6: Sales | AM6: /Cust. | AN6: Vehicles | AO6: Sales | AP6: /Vehic | AQ6: Simulador | AR6: PlayStation | AS6: Arcade | AT6: Total EGA | AU6: Total PRM | AV6: REVENUES | AW6: /Cust. | AZ6: =+'Biyemas S.A.'!AZ6+'Kandiko S.A'!AZ6+'Rebisco S.A.'!AZ6 -> 0 | BJ6: =+'Biyemas S.A.'!BJ6+'Kandiko S.A'!BJ6+'Rebisco S.A.'!BJ6 -> 0 | BK6: =+'Biyemas S.A.'!BK6+'Kandiko S.A'!BK6+'Rebisco S.A.'!BK6 -> 0 | BL6: =+'Biyemas S.A.'!BL6+'Kandiko S.A'!BL6+'Rebisco S.A.'!BL6 -> 0 | BM6: =+'Biyemas S.A.'!BM6+'Kandiko S.A'!BM6+'Rebisco S.A.'!BM6 -> 0 | BN6: =+'Biyemas S.A.'!BN6+'Kandiko S.A'!BN6+'Rebisco S.A.'!BN6 -> 0
A7: =IF(BP7='Datos Biyemas'!A9,'Datos Biyemas'!A9,"") | B7: =IF(BP7=A7,'Datos Biyemas'!B9,"") | C7: =IF(A7=BP7,+'Biyemas S.A.'!C7+'Kandiko S.A'!C7+'Rebisco S.A.'!C7,"") | D7: =IF(A7=BP7,+'Biyemas S.A.'!D7+'Kandiko S.A'!D7+'Rebisco S.A.'!D7,"") | E7: =IF(A7=BP7,+'Biyemas S.A.'!E7+'Kandiko S.A'!E7+'Rebisco S.A.'!E7,"") | F7: =IF(A7=BP7,+'Biyemas S.A.'!F7+'Kandiko S.A'!F7+'Rebisco S.A.'!F7,"") | G7: =IF(A7=BP7,+'Biyemas S.A.'!G7+'Kandiko S.A'!G7+'Rebisco S.A.'!G7,"") | H7: =IF(BP7=A7,IF(E7>0,+G7/E7,0),"") | I7: =IF(A7="","",IF(F7>0,+G7/F7,0)) | J7: =IF(A7="","",IF(G7>0,+G7/C7,0)) | K7: =IF(A7="","",IF(G7>0,+G7/D7,0)) | L7: =IF(A7=BP7,+'Biyemas S.A.'!L7+'Kandiko S.A'!L7+'Rebisco S.A.'!L7,"") | M7: =IF(A7=BP7,+'Biyemas S.A.'!M7+'Kandiko S.A'!M7+'Rebisco S.A.'!M7,"") | N7: =IF(A7=BP7,+'Biyemas S.A.'!N7+'Kandiko S.A'!N7+'Rebisco S.A.'!N7,"") | O7: =IF(A7=BP7,+'Biyemas S.A.'!O7+'Kandiko S.A'!O7+'Rebisco S.A.'!O7,"") | P7: =IF(A7="","",IF(M7>0,+O7/M7,0)) | Q7: =IF(A7="","",IF(N7>0,+O7/N7,0)) | R7: =IF(A7="","",IF(C7>0,+O7/C7,0)) | S7: =IF(A7="","",IF(C7>0,+O7/L7,0)) | T7: =IF(A7="","",IF(G7>0,(G7+O7)/(D7+L7),0)) | U7: =IF(A7="","",IF(D7>0,+L7+D7,0)) | V7: =+'Biyemas S.A.'!V7 | W7: =+'Biyemas S.A.'!W7 | X7: =+'Biyemas S.A.'!X7 | Y7: =+'Biyemas S.A.'!Y7 | Z7: =IF(A7="","",IF(W7>0,+Y7/W7,0)) | AA7: =IF(A7="","",IF(X7>0,+Y7/X7,0)) | AB7: =IF(A7="","",IF(Y7>0,+Y7/K7,0)) | AC7: =IF(A7="","",IF(Y7>0,+Y7/V7,0)) | AD7: =IF(A7=BP7,+G7+O7+Y7,"") | AE7: =IF(A7=BP7,+'Biyemas S.A.'!AE7+'Kandiko S.A'!AE7+'Rebisco S.A.'!AE7,"") | AF7: =IF(A7="","",+AD7-AE7) | AG7: =IF(A7=BP7,+'Biyemas S.A.'!AG7+'Kandiko S.A'!AG7+'Rebisco S.A.'!AG7,"") | AH7: =IF(A7=BP7,+'Biyemas S.A.'!AH7+'Kandiko S.A'!AH7+'Rebisco S.A.'!AH7,"") | AI7: =IF(A7=BP7,+'Biyemas S.A.'!AI7+'Kandiko S.A'!AI7+'Rebisco S.A.'!AI7,"") | AJ7: =IF(A7="","",IF(AI7>0,+AI7/C7,0)) | AK7: =IF(A7="","",+G7+O7+AI7+Y7) | AL7: =IF(A7=BP7,+'Biyemas S.A.'!AL7+'Kandiko S.A'!AL7+'Rebisco S.A.'!AL7,"") | AM7: =IF(A7="","",IF(AL7>0,+AL7/C7,0)) | AN7: =IF(A7=BP7,+'Biyemas S.A.'!AN7+'Kandiko S.A'!AN7+'Rebisco S.A.'!AN7,"") | AO7: =IF(A7=BP7,+'Biyemas S.A.'!AO7+'Kandiko S.A'!AO7+'Rebisco S.A.'!AO7,"") | AP7: =IF(A7="","",IF(AN7>0,+AO7/AN7,0)) | AQ7: =IF(A7=BP7,+'Biyemas S.A.'!AQ7+'Kandiko S.A'!AQ7+'Rebisco S.A.'!AQ7,"") | AR7: =IF(A7=BP7,+'Biyemas S.A.'!AR7+'Kandiko S.A'!AR7+'Rebisco S.A.'!AR7,"") | AS7: =IF(A7=BP7,+'Biyemas S.A.'!AS7+'Kandiko S.A'!AS7+'Rebisco S.A.'!AS7,"") | AT7: =IF(A7=BP7,+'Biyemas S.A.'!AT7+'Kandiko S.A'!AT7+'Rebisco S.A.'!AT7,"") | AU7: =IFERROR('Biyemas S.A.'!AU7+'Kandiko S.A'!AU7+'Rebisco S.A.'!AU7,0) -> 0 | AV7: =IF(A7="","",+AD7+AI7+AL7+AO7) | AW7: =IF(A7="","",IF(AV7>0,+AV7/C7,0)) | AY7: =IF(A7=BP7,+'Biyemas S.A.'!AY7+'Kandiko S.A'!AY7+'Rebisco S.A.'!AY7,"") | AZ7: =IF(A7="","",IF($AZ$6>0,+AY7-$AZ$6,)) | BA7: =IF(A7=BP7,+'Biyemas S.A.'!BA7+'Kandiko S.A'!BA7+'Rebisco S.A.'!BA7,"") | BB7: =IF(A7="","",IF(BA7>0,(C7-BA7)/BA7,100%)) | BC7: =IF(A7=BP7,+'Biyemas S.A.'!BC7+'Kandiko S.A'!BC7+'Rebisco S.A.'!BC7,"") | BD7: =IF(A7="","",IF(AN7=BC7,0,IF(BC7>0,(AN7-BC7)/BC7,1))) | BE7: =IF(A7="","",VLOOKUP(B7,'Datos Consolidados'!B9:BF46,53,0)) | BF7: =IF(A7="","",VLOOKUP(B7,'Datos Consolidados'!B9:BF46,54,0)) | BG7: =IF(A7="","",VLOOKUP(B7,'Datos Consolidados'!B9:BF46,55,0)) | BH7: =IF(A7="","",VLOOKUP(B7,'Datos Consolidados'!B9:BF46,51,0)) | BI7: =IF(A7="","",VLOOKUP(B7,'Datos Consolidados'!B9:BF46,52,0)) | BJ7: =IF(A7="","",+AV7/$BJ$6-1) | BK7: =IF(A7="","",+AD7/$BK$6-1) | BL7: =IF(A7="","",+AI7/$BL$6-1) | BM7: =IF(A7="","",AL7/$BM$6-1) | BN7: =+'Biyemas S.A.'!BN7 | BP7: =+'Biyemas S.A.'!BP7 -> Sab/Sat
A8: =IF(BP8='Datos Biyemas'!A10,'Datos Biyemas'!A10,"") | B8: =IF(BP8=A8,'Datos Biyemas'!B10,"") | C8: =IF(A8=BP8,+'Biyemas S.A.'!C8+'Kandiko S.A'!C8+'Rebisco S.A.'!C8,"") | D8: =IF(A8=BP8,+'Biyemas S.A.'!D8+'Kandiko S.A'!D8+'Rebisco S.A.'!D8,"") | E8: =IF(A8=BP8,+'Biyemas S.A.'!E8+'Kandiko S.A'!E8+'Rebisco S.A.'!E8,"") | F8: =IF(A8=BP8,+'Biyemas S.A.'!F8+'Kandiko S.A'!F8+'Rebisco S.A.'!F8,"") | G8: =IF(A8=BP8,+'Biyemas S.A.'!G8+'Kandiko S.A'!G8+'Rebisco S.A.'!G8,"") | H8: =IF(BP8=A8,IF(E8>0,+G8/E8,0),"") | I8: =IF(A8="","",IF(F8>0,+G8/F8,0)) | J8: =IF(A8="","",IF(G8>0,+G8/C8,0)) | K8: =IF(A8="","",IF(G8>0,+G8/D8,0)) | L8: =IF(A8=BP8,+'Biyemas S.A.'!L8+'Kandiko S.A'!L8+'Rebisco S.A.'!L8,"") | M8: =IF(A8=BP8,+'Biyemas S.A.'!M8+'Kandiko S.A'!M8+'Rebisco S.A.'!M8,"") | N8: =IF(A8=BP8,+'Biyemas S.A.'!N8+'Kandiko S.A'!N8+'Rebisco S.A.'!N8,"") | O8: =IF(A8=BP8,+'Biyemas S.A.'!O8+'Kandiko S.A'!O8+'Rebisco S.A.'!O8,"") | P8: =IF(A8="","",IF(M8>0,+O8/M8,0)) | Q8: =IF(A8="","",IF(N8>0,+O8/N8,0)) | R8: =IF(A8="","",IF(C8>0,+O8/C8,0)) | S8: =IF(A8="","",IF(C8>0,+O8/L8,0)) | T8: =IF(A8="","",IF(G8>0,(G8+O8)/(D8+L8),0)) | U8: =IF(A8="","",IF(D8>0,+L8+D8,0)) | V8: =IF(A8="","",VLOOKUP(B8,'Datos Biyemas'!B10:BB47,21,0)) | W8: =IF(A8="","",VLOOKUP(B8,'Datos Biyemas'!B10:BB47,22,0)) | X8: =IF(A8="","",VLOOKUP(B8,'Datos Biyemas'!B10:BB47,23,0)) | Y8: =IF(A8="","",VLOOKUP(B8,'Datos Biyemas'!B10:BB47,24,0)) | Z8: =IF(A8="","",IF(W8>0,+Y8/W8,0)) | AA8: =IF(A8="","",IF(X8>0,+Y8/X8,0)) | AB8: =IF(A8="","",IF(Y8>0,+Y8/K8,0)) | AC8: =IF(A8="","",IF(Y8>0,+Y8/V8,0)) | AD8: =IF(A8=BP8,+G8+O8+Y8,"") | AE8: =IF(A8=BP8,+'Biyemas S.A.'!AE8+'Kandiko S.A'!AE8+'Rebisco S.A.'!AE8,"") | AF8: =IF(A8="","",+AD8-AE8) | AG8: =IF(A8=BP8,+'Biyemas S.A.'!AG8+'Kandiko S.A'!AG8+'Rebisco S.A.'!AG8,"") | AH8: =IF(A8=BP8,+'Biyemas S.A.'!AH8+'Kandiko S.A'!AH8+'Rebisco S.A.'!AH8,"") | AI8: =IF(A8=BP8,+'Biyemas S.A.'!AI8+'Kandiko S.A'!AI8+'Rebisco S.A.'!AI8,"") | AJ8: =IF(A8="","",IF(AI8>0,+AI8/C8,0)) | AK8: =IF(A8="","",+G8+O8+AI8+Y8) | AL8: =IF(A8=BP8,+'Biyemas S.A.'!AL8+'Kandiko S.A'!AL8+'Rebisco S.A.'!AL8,"") | AM8: =IF(A8="","",IF(AL8>0,+AL8/C8,0)) | AN8: =IF(A8=BP8,+'Biyemas S.A.'!AN8+'Kandiko S.A'!AN8+'Rebisco S.A.'!AN8,"") | AO8: =IF(A8=BP8,+'Biyemas S.A.'!AO8+'Kandiko S.A'!AO8+'Rebisco S.A.'!AO8,"") | AP8: =IF(A8="","",IF(AN8>0,+AO8/AN8,0)) | AQ8: =IF(A8=BP8,+'Biyemas S.A.'!AQ8+'Kandiko S.A'!AQ8+'Rebisco S.A.'!AQ8,"") | AR8: =IF(A8=BP8,+'Biyemas S.A.'!AR8+'Kandiko S.A'!AR8+'Rebisco S.A.'!AR8,"") | AS8: =IF(A8=BP8,+'Biyemas S.A.'!AS8+'Kandiko S.A'!AS8+'Rebisco S.A.'!AS8,"") | AT8: =IF(A8=BP8,+'Biyemas S.A.'!AT8+'Kandiko S.A'!AT8+'Rebisco S.A.'!AT8,"") | AU8: =IFERROR('Biyemas S.A.'!AU8+'Kandiko S.A'!AU8+'Rebisco S.A.'!AU8,0) -> 0 | AV8: =IF(A8="","",+AD8+AI8+AL8+AO8) | AW8: =IF(A8="","",IF(AV8>0,+AV8/C8,0)) | AY8: =IF(A8=BP8,+'Biyemas S.A.'!AY8+'Kandiko S.A'!AY8+'Rebisco S.A.'!AY8,"") | AZ8: =IF(A8="","",IF($AZ$6>0,+AY8-$AZ$6,)) | BA8: =IF(A8=BP8,+'Biyemas S.A.'!BA8+'Kandiko S.A'!BA8+'Rebisco S.A.'!BA8,"") | BB8: =IF(A8="","",IF(BA8>0,(C8-BA8)/BA8,100%)) | BC8: =IF(A8=BP8,+'Biyemas S.A.'!BC8+'Kandiko S.A'!BC8+'Rebisco S.A.'!BC8,"") | BD8: =IF(A8="","",IF(AN8=BC8,0,IF(BC8>0,(AN8-BC8)/BC8,1))) | BE8: =IF(A8="","",VLOOKUP(B8,'Datos Consolidados'!B10:BF47,53,0)) | BF8: =IF(A8="","",VLOOKUP(B8,'Datos Consolidados'!B10:BF47,54,0)) | BG8: =IF(A8="","",VLOOKUP(B8,'Datos Consolidados'!B10:BF47,55,0)) | BH8: =IF(A8="","",VLOOKUP(B8,'Datos Consolidados'!B10:BF47,51,0)) | BI8: =IF(A8="","",VLOOKUP(B8,'Datos Consolidados'!B10:BF47,52,0)) | BJ8: =IF(A8="","",+AV8/$BJ$6-1) | BK8: =IF(A8="","",+AD8/$BK$6-1) | BL8: =IF(A8="","",+AI8/$BL$6-1) | BM8: =IF(A8="","",AL8/$BM$6-1) | BN8: =+'Biyemas S.A.'!BN8 | BP8: =+'Biyemas S.A.'!BP8 -> Dom/Sun
A9: =IF(BP9='Datos Biyemas'!A11,'Datos Biyemas'!A11,"") | B9: =IF(BP9=A9,'Datos Biyemas'!B11,"") | C9: =IF(A9=BP9,+'Biyemas S.A.'!C9+'Kandiko S.A'!C9+'Rebisco S.A.'!C9,"") | D9: =IF(A9=BP9,+'Biyemas S.A.'!D9+'Kandiko S.A'!D9+'Rebisco S.A.'!D9,"") | E9: =IF(A9=BP9,+'Biyemas S.A.'!E9+'Kandiko S.A'!E9+'Rebisco S.A.'!E9,"") | F9: =IF(A9=BP9,+'Biyemas S.A.'!F9+'Kandiko S.A'!F9+'Rebisco S.A.'!F9,"") | G9: =IF(A9=BP9,+'Biyemas S.A.'!G9+'Kandiko S.A'!G9+'Rebisco S.A.'!G9,"") | H9: =IF(BP9=A9,IF(E9>0,+G9/E9,0),"") | I9: =IF(A9="","",IF(F9>0,+G9/F9,0)) | J9: =IF(A9="","",IF(G9>0,+G9/C9,0)) | K9: =IF(A9="","",IF(G9>0,+G9/D9,0)) | L9: =IF(A9=BP9,+'Biyemas S.A.'!L9+'Kandiko S.A'!L9+'Rebisco S.A.'!L9,"") | M9: =IF(A9=BP9,+'Biyemas S.A.'!M9+'Kandiko S.A'!M9+'Rebisco S.A.'!M9,"") | N9: =IF(A9=BP9,+'Biyemas S.A.'!N9+'Kandiko S.A'!N9+'Rebisco S.A.'!N9,"") | O9: =IF(A9=BP9,+'Biyemas S.A.'!O9+'Kandiko S.A'!O9+'Rebisco S.A.'!O9,"") | P9: =IF(A9="","",IF(M9>0,+O9/M9,0)) | Q9: =IF(A9="","",IF(N9>0,+O9/N9,0)) | R9: =IF(A9="","",IF(C9>0,+O9/C9,0)) | S9: =IF(A9="","",IF(C9>0,+O9/L9,0)) | T9: =IF(A9="","",IF(G9>0,(G9+O9)/(D9+L9),0)) | U9: =IF(A9="","",IF(D9>0,+L9+D9,0)) | V9: =IF(A9="","",VLOOKUP(B9,'Datos Biyemas'!B11:BB48,21,0)) | W9: =IF(A9="","",VLOOKUP(B9,'Datos Biyemas'!B11:BB48,22,0)) | X9: =IF(A9="","",VLOOKUP(B9,'Datos Biyemas'!B11:BB48,23,0)) | Y9: =IF(A9="","",VLOOKUP(B9,'Datos Biyemas'!B11:BB48,24,0)) | Z9: =IF(A9="","",IF(W9>0,+Y9/W9,0)) | AA9: =IF(A9="","",IF(X9>0,+Y9/X9,0)) | AB9: =IF(A9="","",IF(Y9>0,+Y9/K9,0)) | AC9: =IF(A9="","",IF(Y9>0,+Y9/V9,0)) | AD9: =IF(A9=BP9,+G9+O9+Y9,"") | AE9: =IF(A9=BP9,+'Biyemas S.A.'!AE9+'Kandiko S.A'!AE9+'Rebisco S.A.'!AE9,"") | AF9: =IF(A9="","",+AD9-AE9) | AG9: =IF(A9=BP9,+'Biyemas S.A.'!AG9+'Kandiko S.A'!AG9+'Rebisco S.A.'!AG9,"") | AH9: =IF(A9=BP9,+'Biyemas S.A.'!AH9+'Kandiko S.A'!AH9+'Rebisco S.A.'!AH9,"") | AI9: =IF(A9=BP9,+'Biyemas S.A.'!AI9+'Kandiko S.A'!AI9+'Rebisco S.A.'!AI9,"") | AJ9: =IF(A9="","",IF(AI9>0,+AI9/C9,0)) | AK9: =IF(A9="","",+G9+O9+AI9+Y9) | AL9: =IF(A9=BP9,+'Biyemas S.A.'!AL9+'Kandiko S.A'!AL9+'Rebisco S.A.'!AL9,"") | AM9: =IF(A9="","",IF(AL9>0,+AL9/C9,0)) | AN9: =IF(A9=BP9,+'Biyemas S.A.'!AN9+'Kandiko S.A'!AN9+'Rebisco S.A.'!AN9,"") | AO9: =IF(A9=BP9,+'Biyemas S.A.'!AO9+'Kandiko S.A'!AO9+'Rebisco S.A.'!AO9,"") | AP9: =IF(A9="","",IF(AN9>0,+AO9/AN9,0)) | AQ9: =IF(A9=BP9,+'Biyemas S.A.'!AQ9+'Kandiko S.A'!AQ9+'Rebisco S.A.'!AQ9,"") | AR9: =IF(A9=BP9,+'Biyemas S.A.'!AR9+'Kandiko S.A'!AR9+'Rebisco S.A.'!AR9,"") | AS9: =IF(A9=BP9,+'Biyemas S.A.'!AS9+'Kandiko S.A'!AS9+'Rebisco S.A.'!AS9,"") | AT9: =IF(A9=BP9,+'Biyemas S.A.'!AT9+'Kandiko S.A'!AT9+'Rebisco S.A.'!AT9,"") | AU9: =IFERROR('Biyemas S.A.'!AU9+'Kandiko S.A'!AU9+'Rebisco S.A.'!AU9,0) -> 0 | AV9: =IF(A9="","",+AD9+AI9+AL9+AO9) | AW9: =IF(A9="","",IF(AV9>0,+AV9/C9,0)) | AY9: =IF(A9=BP9,+'Biyemas S.A.'!AY9+'Kandiko S.A'!AY9+'Rebisco S.A.'!AY9,"") | AZ9: =IF(A9="","",IF($AZ$6>0,+AY9-$AZ$6,)) | BA9: =IF(A9=BP9,+'Biyemas S.A.'!BA9+'Kandiko S.A'!BA9+'Rebisco S.A.'!BA9,"") | BB9: =IF(A9="","",IF(BA9>0,(C9-BA9)/BA9,100%)) | BC9: =IF(A9=BP9,+'Biyemas S.A.'!BC9+'Kandiko S.A'!BC9+'Rebisco S.A.'!BC9,"") | BD9: =IF(A9="","",IF(AN9=BC9,0,IF(BC9>0,(AN9-BC9)/BC9,1))) | BE9: =IF(A9="","",VLOOKUP(B9,'Datos Consolidados'!B11:BF48,53,0)) | BF9: =IF(A9="","",VLOOKUP(B9,'Datos Consolidados'!B11:BF48,54,0)) | BG9: =IF(A9="","",VLOOKUP(B9,'Datos Consolidados'!B11:BF48,55,0)) | BH9: =IF(A9="","",VLOOKUP(B9,'Datos Consolidados'!B11:BF48,51,0)) | BI9: =IF(A9="","",VLOOKUP(B9,'Datos Consolidados'!B11:BF48,52,0)) | BJ9: =IF(A9="","",+AV9/$BJ$6-1) | BK9: =IF(A9="","",+AD9/$BK$6-1) | BL9: =IF(A9="","",+AI9/$BL$6-1) | BM9: =IF(A9="","",AL9/$BM$6-1) | BN9: =+'Biyemas S.A.'!BN9 | BP9: =+'Biyemas S.A.'!BP9 -> Lun/Mon
A10: =IF(BP10='Datos Biyemas'!A12,'Datos Biyemas'!A12,"") | B10: =IF(BP10=A10,'Datos Biyemas'!B12,"") | C10: =IF(A10=BP10,+'Biyemas S.A.'!C10+'Kandiko S.A'!C10+'Rebisco S.A.'!C10,"") | D10: =IF(A10=BP10,+'Biyemas S.A.'!D10+'Kandiko S.A'!D10+'Rebisco S.A.'!D10,"") | E10: =IF(A10=BP10,+'Biyemas S.A.'!E10+'Kandiko S.A'!E10+'Rebisco S.A.'!E10,"") | F10: =IF(A10=BP10,+'Biyemas S.A.'!F10+'Kandiko S.A'!F10+'Rebisco S.A.'!F10,"") | G10: =IF(A10=BP10,+'Biyemas S.A.'!G10+'Kandiko S.A'!G10+'Rebisco S.A.'!G10,"") | H10: =IF(BP10=A10,IF(E10>0,+G10/E10,0),"") | I10: =IF(A10="","",IF(F10>0,+G10/F10,0)) | J10: =IF(A10="","",IF(G10>0,+G10/C10,0)) | K10: =IF(A10="","",IF(G10>0,+G10/D10,0)) | L10: =IF(A10=BP10,+'Biyemas S.A.'!L10+'Kandiko S.A'!L10+'Rebisco S.A.'!L10,"") | M10: =IF(A10=BP10,+'Biyemas S.A.'!M10+'Kandiko S.A'!M10+'Rebisco S.A.'!M10,"") | N10: =IF(A10=BP10,+'Biyemas S.A.'!N10+'Kandiko S.A'!N10+'Rebisco S.A.'!N10,"") | O10: =IF(A10=BP10,+'Biyemas S.A.'!O10+'Kandiko S.A'!O10+'Rebisco S.A.'!O10,"") | P10: =IF(A10="","",IF(M10>0,+O10/M10,0)) | Q10: =IF(A10="","",IF(N10>0,+O10/N10,0)) | R10: =IF(A10="","",IF(C10>0,+O10/C10,0)) | S10: =IF(A10="","",IF(C10>0,+O10/L10,0)) | T10: =IF(A10="","",IF(G10>0,(G10+O10)/(D10+L10),0)) | U10: =IF(A10="","",IF(D10>0,+L10+D10,0)) | V10: =IF(A10="","",VLOOKUP(B10,'Datos Biyemas'!B12:BB49,21,0)) | W10: =IF(A10="","",VLOOKUP(B10,'Datos Biyemas'!B12:BB49,22,0)) | X10: =IF(A10="","",VLOOKUP(B10,'Datos Biyemas'!B12:BB49,23,0)) | Y10: =IF(A10="","",VLOOKUP(B10,'Datos Biyemas'!B12:BB49,24,0)) | Z10: =IF(A10="","",IF(W10>0,+Y10/W10,0)) | AA10: =IF(A10="","",IF(X10>0,+Y10/X10,0)) | AB10: =IF(A10="","",IF(Y10>0,+Y10/K10,0)) | AC10: =IF(A10="","",IF(Y10>0,+Y10/V10,0)) | AD10: =IF(A10=BP10,+G10+O10+Y10,"") | AE10: =IF(A10=BP10,+'Biyemas S.A.'!AE10+'Kandiko S.A'!AE10+'Rebisco S.A.'!AE10,"") | AF10: =IF(A10="","",+AD10-AE10) | AG10: =IF(A10=BP10,+'Biyemas S.A.'!AG10+'Kandiko S.A'!AG10+'Rebisco S.A.'!AG10,"") | AH10: =IF(A10=BP10,+'Biyemas S.A.'!AH10+'Kandiko S.A'!AH10+'Rebisco S.A.'!AH10,"") | AI10: =IF(A10=BP10,+'Biyemas S.A.'!AI10+'Kandiko S.A'!AI10+'Rebisco S.A.'!AI10,"") | AJ10: =IF(A10="","",IF(AI10>0,+AI10/C10,0)) | AK10: =IF(A10="","",+G10+O10+AI10+Y10) | AL10: =IF(A10=BP10,+'Biyemas S.A.'!AL10+'Kandiko S.A'!AL10+'Rebisco S.A.'!AL10,"") | AM10: =IF(A10="","",IF(AL10>0,+AL10/C10,0)) | AN10: =IF(A10=BP10,+'Biyemas S.A.'!AN10+'Kandiko S.A'!AN10+'Rebisco S.A.'!AN10,"") | AO10: =IF(A10=BP10,+'Biyemas S.A.'!AO10+'Kandiko S.A'!AO10+'Rebisco S.A.'!AO10,"") | AP10: =IF(A10="","",IF(AN10>0,+AO10/AN10,0)) | AQ10: =IF(A10=BP10,+'Biyemas S.A.'!AQ10+'Kandiko S.A'!AQ10+'Rebisco S.A.'!AQ10,"") | AR10: =IF(A10=BP10,+'Biyemas S.A.'!AR10+'Kandiko S.A'!AR10+'Rebisco S.A.'!AR10,"") | AS10: =IF(A10=BP10,+'Biyemas S.A.'!AS10+'Kandiko S.A'!AS10+'Rebisco S.A.'!AS10,"") | AT10: =IF(A10=BP10,+'Biyemas S.A.'!AT10+'Kandiko S.A'!AT10+'Rebisco S.A.'!AT10,"") | AU10: =IFERROR('Biyemas S.A.'!AU10+'Kandiko S.A'!AU10+'Rebisco S.A.'!AU10,0) -> 0 | AV10: =IF(A10="","",+AD10+AI10+AL10+AO10) | AW10: =IF(A10="","",IF(AV10>0,+AV10/C10,0)) | AY10: =IF(A10=BP10,+'Biyemas S.A.'!AY10+'Kandiko S.A'!AY10+'Rebisco S.A.'!AY10,"") | AZ10: =IF(A10="","",IF($AZ$6>0,+AY10-$AZ$6,)) | BA10: =IF(A10=BP10,+'Biyemas S.A.'!BA10+'Kandiko S.A'!BA10+'Rebisco S.A.'!BA10,"") | BB10: =IF(A10="","",IF(BA10>0,(C10-BA10)/BA10,100%)) | BC10: =IF(A10=BP10,+'Biyemas S.A.'!BC10+'Kandiko S.A'!BC10+'Rebisco S.A.'!BC10,"") | BD10: =IF(A10="","",IF(AN10=BC10,0,IF(BC10>0,(AN10-BC10)/BC10,1))) | BE10: =IF(A10="","",VLOOKUP(B10,'Datos Consolidados'!B12:BF49,53,0)) | BF10: =IF(A10="","",VLOOKUP(B10,'Datos Consolidados'!B12:BF49,54,0)) | BG10: =IF(A10="","",VLOOKUP(B10,'Datos Consolidados'!B12:BF49,55,0)) | BH10: =IF(A10="","",VLOOKUP(B10,'Datos Consolidados'!B12:BF49,51,0)) | BI10: =IF(A10="","",VLOOKUP(B10,'Datos Consolidados'!B12:BF49,52,0)) | BJ10: =IF(A10="","",+AV10/$BJ$6-1) | BK10: =IF(A10="","",+AD10/$BK$6-1) | BL10: =IF(A10="","",+AI10/$BL$6-1) | BM10: =IF(A10="","",AL10/$BM$6-1) | BN10: =+'Biyemas S.A.'!BN10 | BP10: =+'Biyemas S.A.'!BP10 -> Mar/Tue
A11: =IF(BP11='Datos Biyemas'!A13,'Datos Biyemas'!A13,"") | B11: =IF(BP11=A11,'Datos Biyemas'!B13,"") | C11: =IF(A11=BP11,+'Biyemas S.A.'!C11+'Kandiko S.A'!C11+'Rebisco S.A.'!C11,"") | D11: =IF(A11=BP11,+'Biyemas S.A.'!D11+'Kandiko S.A'!D11+'Rebisco S.A.'!D11,"") | E11: =IF(A11=BP11,+'Biyemas S.A.'!E11+'Kandiko S.A'!E11+'Rebisco S.A.'!E11,"") | F11: =IF(A11=BP11,+'Biyemas S.A.'!F11+'Kandiko S.A'!F11+'Rebisco S.A.'!F11,"") | G11: =IF(A11=BP11,+'Biyemas S.A.'!G11+'Kandiko S.A'!G11+'Rebisco S.A.'!G11,"") | H11: =IF(BP11=A11,IF(E11>0,+G11/E11,0),"") | I11: =IF(A11="","",IF(F11>0,+G11/F11,0)) | J11: =IF(A11="","",IF(G11>0,+G11/C11,0)) | K11: =IF(A11="","",IF(G11>0,+G11/D11,0)) | L11: =IF(A11=BP11,+'Biyemas S.A.'!L11+'Kandiko S.A'!L11+'Rebisco S.A.'!L11,"") | M11: =IF(A11=BP11,+'Biyemas S.A.'!M11+'Kandiko S.A'!M11+'Rebisco S.A.'!M11,"") | N11: =IF(A11=BP11,+'Biyemas S.A.'!N11+'Kandiko S.A'!N11+'Rebisco S.A.'!N11,"") | O11: =IF(A11=BP11,+'Biyemas S.A.'!O11+'Kandiko S.A'!O11+'Rebisco S.A.'!O11,"") | P11: =IF(A11="","",IF(M11>0,+O11/M11,0)) | Q11: =IF(A11="","",IF(N11>0,+O11/N11,0)) | R11: =IF(A11="","",IF(C11>0,+O11/C11,0)) | S11: =IF(A11="","",IF(C11>0,+O11/L11,0)) | T11: =IF(A11="","",IF(G11>0,(G11+O11)/(D11+L11),0)) | U11: =IF(A11="","",IF(D11>0,+L11+D11,0)) | V11: =IF(A11="","",VLOOKUP(B11,'Datos Biyemas'!B13:BB50,21,0)) | W11: =IF(A11="","",VLOOKUP(B11,'Datos Biyemas'!B13:BB50,22,0)) | X11: =IF(A11="","",VLOOKUP(B11,'Datos Biyemas'!B13:BB50,23,0)) | Y11: =IF(A11="","",VLOOKUP(B11,'Datos Biyemas'!B13:BB50,24,0)) | Z11: =IF(A11="","",IF(W11>0,+Y11/W11,0)) | AA11: =IF(A11="","",IF(X11>0,+Y11/X11,0)) | AB11: =IF(A11="","",IF(Y11>0,+Y11/K11,0)) | AC11: =IF(A11="","",IF(Y11>0,+Y11/V11,0)) | AD11: =IF(A11=BP11,+G11+O11+Y11,"") | AE11: =IF(A11=BP11,+'Biyemas S.A.'!AE11+'Kandiko S.A'!AE11+'Rebisco S.A.'!AE11,"") | AF11: =IF(A11="","",+AD11-AE11) | AG11: =IF(A11=BP11,+'Biyemas S.A.'!AG11+'Kandiko S.A'!AG11+'Rebisco S.A.'!AG11,"") | AH11: =IF(A11=BP11,+'Biyemas S.A.'!AH11+'Kandiko S.A'!AH11+'Rebisco S.A.'!AH11,"") | AI11: =IF(A11=BP11,+'Biyemas S.A.'!AI11+'Kandiko S.A'!AI11+'Rebisco S.A.'!AI11,"") | AJ11: =IF(A11="","",IF(AI11>0,+AI11/C11,0)) | AK11: =IF(A11="","",+G11+O11+AI11+Y11) | AL11: =IF(A11=BP11,+'Biyemas S.A.'!AL11+'Kandiko S.A'!AL11+'Rebisco S.A.'!AL11,"") | AM11: =IF(A11="","",IF(AL11>0,+AL11/C11,0)) | AN11: =IF(A11=BP11,+'Biyemas S.A.'!AN11+'Kandiko S.A'!AN11+'Rebisco S.A.'!AN11,"") | AO11: =IF(A11=BP11,+'Biyemas S.A.'!AO11+'Kandiko S.A'!AO11+'Rebisco S.A.'!AO11,"") | AP11: =IF(A11="","",IF(AN11>0,+AO11/AN11,0)) | AQ11: =IF(A11=BP11,+'Biyemas S.A.'!AQ11+'Kandiko S.A'!AQ11+'Rebisco S.A.'!AQ11,"") | AR11: =IF(A11=BP11,+'Biyemas S.A.'!AR11+'Kandiko S.A'!AR11+'Rebisco S.A.'!AR11,"") | AS11: =IF(A11=BP11,+'Biyemas S.A.'!AS11+'Kandiko S.A'!AS11+'Rebisco S.A.'!AS11,"") | AT11: =IF(A11=BP11,+'Biyemas S.A.'!AT11+'Kandiko S.A'!AT11+'Rebisco S.A.'!AT11,"") | AU11: =IFERROR('Biyemas S.A.'!AU11+'Kandiko S.A'!AU11+'Rebisco S.A.'!AU11,0) -> 0 | AV11: =IF(A11="","",+AD11+AI11+AL11+AO11) | AW11: =IF(A11="","",IF(AV11>0,+AV11/C11,0)) | AY11: =IF(A11=BP11,+'Biyemas S.A.'!AY11+'Kandiko S.A'!AY11+'Rebisco S.A.'!AY11,"") | AZ11: =IF(A11="","",IF($AZ$6>0,+AY11-$AZ$6,)) | BA11: =IF(A11=BP11,+'Biyemas S.A.'!BA11+'Kandiko S.A'!BA11+'Rebisco S.A.'!BA11,"") | BB11: =IF(A11="","",IF(BA11>0,(C11-BA11)/BA11,100%)) | BC11: =IF(A11=BP11,+'Biyemas S.A.'!BC11+'Kandiko S.A'!BC11+'Rebisco S.A.'!BC11,"") | BD11: =IF(A11="","",IF(AN11=BC11,0,IF(BC11>0,(AN11-BC11)/BC11,1))) | BE11: =IF(A11="","",VLOOKUP(B11,'Datos Consolidados'!B13:BF50,53,0)) | BF11: =IF(A11="","",VLOOKUP(B11,'Datos Consolidados'!B13:BF50,54,0)) | BG11: =IF(A11="","",VLOOKUP(B11,'Datos Consolidados'!B13:BF50,55,0)) | BH11: =IF(A11="","",VLOOKUP(B11,'Datos Consolidados'!B13:BF50,51,0)) | BI11: =IF(A11="","",VLOOKUP(B11,'Datos Consolidados'!B13:BF50,52,0)) | BJ11: =IF(A11="","",+AV11/$BJ$6-1) | BK11: =IF(A11="","",+AD11/$BK$6-1) | BL11: =IF(A11="","",+AI11/$BL$6-1) | BM11: =IF(A11="","",AL11/$BM$6-1) | BN11: =+'Biyemas S.A.'!BN11 | BP11: =+'Biyemas S.A.'!BP11 -> Mie/Wed
A12: =IF(BP12='Datos Biyemas'!A14,'Datos Biyemas'!A14,"") | B12: =IF(BP12=A12,'Datos Biyemas'!B14,"") | C12: =IF(A12=BP12,+'Biyemas S.A.'!C12+'Kandiko S.A'!C12+'Rebisco S.A.'!C12,"") | D12: =IF(A12=BP12,+'Biyemas S.A.'!D12+'Kandiko S.A'!D12+'Rebisco S.A.'!D12,"") | E12: =IF(A12=BP12,+'Biyemas S.A.'!E12+'Kandiko S.A'!E12+'Rebisco S.A.'!E12,"") | F12: =IF(A12=BP12,+'Biyemas S.A.'!F12+'Kandiko S.A'!F12+'Rebisco S.A.'!F12,"") | G12: =IF(A12=BP12,+'Biyemas S.A.'!G12+'Kandiko S.A'!G12+'Rebisco S.A.'!G12,"") | H12: =IF(BP12=A12,IF(E12>0,+G12/E12,0),"") | I12: =IF(A12="","",IF(F12>0,+G12/F12,0)) | J12: =IF(A12="","",IF(G12>0,+G12/C12,0)) | K12: =IF(A12="","",IF(G12>0,+G12/D12,0)) | L12: =IF(A12=BP12,+'Biyemas S.A.'!L12+'Kandiko S.A'!L12+'Rebisco S.A.'!L12,"") | M12: =IF(A12=BP12,+'Biyemas S.A.'!M12+'Kandiko S.A'!M12+'Rebisco S.A.'!M12,"") | N12: =IF(A12=BP12,+'Biyemas S.A.'!N12+'Kandiko S.A'!N12+'Rebisco S.A.'!N12,"") | O12: =IF(A12=BP12,+'Biyemas S.A.'!O12+'Kandiko S.A'!O12+'Rebisco S.A.'!O12,"") | P12: =IF(A12="","",IF(M12>0,+O12/M12,0)) | Q12: =IF(A12="","",IF(N12>0,+O12/N12,0)) | R12: =IF(A12="","",IF(C12>0,+O12/C12,0)) | S12: =IF(A12="","",IF(C12>0,+O12/L12,0)) | T12: =IF(A12="","",IF(G12>0,(G12+O12)/(D12+L12),0)) | U12: =IF(A12="","",IF(D12>0,+L12+D12,0)) | V12: =IF(A12="","",VLOOKUP(B12,'Datos Biyemas'!B14:BB51,21,0)) | W12: =IF(A12="","",VLOOKUP(B12,'Datos Biyemas'!B14:BB51,22,0)) | X12: =IF(A12="","",VLOOKUP(B12,'Datos Biyemas'!B14:BB51,23,0)) | Y12: =IF(A12="","",VLOOKUP(B12,'Datos Biyemas'!B14:BB51,24,0)) | Z12: =IF(A12="","",IF(W12>0,+Y12/W12,0)) | AA12: =IF(A12="","",IF(X12>0,+Y12/X12,0)) | AB12: =IF(A12="","",IF(Y12>0,+Y12/K12,0)) | AC12: =IF(A12="","",IF(Y12>0,+Y12/V12,0)) | AD12: =IF(A12=BP12,+G12+O12+Y12,"") | AE12: =IF(A12=BP12,+'Biyemas S.A.'!AE12+'Kandiko S.A'!AE12+'Rebisco S.A.'!AE12,"") | AF12: =IF(A12="","",+AD12-AE12) | AG12: =IF(A12=BP12,+'Biyemas S.A.'!AG12+'Kandiko S.A'!AG12+'Rebisco S.A.'!AG12,"") | AH12: =IF(A12=BP12,+'Biyemas S.A.'!AH12+'Kandiko S.A'!AH12+'Rebisco S.A.'!AH12,"") | AI12: =IF(A12=BP12,+'Biyemas S.A.'!AI12+'Kandiko S.A'!AI12+'Rebisco S.A.'!AI12,"") | AJ12: =IF(A12="","",IF(AI12>0,+AI12/C12,0)) | AK12: =IF(A12="","",+G12+O12+AI12+Y12) | AL12: =IF(A12=BP12,+'Biyemas S.A.'!AL12+'Kandiko S.A'!AL12+'Rebisco S.A.'!AL12,"") | AM12: =IF(A12="","",IF(AL12>0,+AL12/C12,0)) | AN12: =IF(A12=BP12,+'Biyemas S.A.'!AN12+'Kandiko S.A'!AN12+'Rebisco S.A.'!AN12,"") | AO12: =IF(A12=BP12,+'Biyemas S.A.'!AO12+'Kandiko S.A'!AO12+'Rebisco S.A.'!AO12,"") | AP12: =IF(A12="","",IF(AN12>0,+AO12/AN12,0)) | AQ12: =IF(A12=BP12,+'Biyemas S.A.'!AQ12+'Kandiko S.A'!AQ12+'Rebisco S.A.'!AQ12,"") | AR12: =IF(A12=BP12,+'Biyemas S.A.'!AR12+'Kandiko S.A'!AR12+'Rebisco S.A.'!AR12,"") | AS12: =IF(A12=BP12,+'Biyemas S.A.'!AS12+'Kandiko S.A'!AS12+'Rebisco S.A.'!AS12,"") | AT12: =IF(A12=BP12,+'Biyemas S.A.'!AT12+'Kandiko S.A'!AT12+'Rebisco S.A.'!AT12,"") | AU12: =IFERROR('Biyemas S.A.'!AU12+'Kandiko S.A'!AU12+'Rebisco S.A.'!AU12,0) -> 0 | AV12: =IF(A12="","",+AD12+AI12+AL12+AO12) | AW12: =IF(A12="","",IF(AV12>0,+AV12/C12,0)) | AY12: =IF(A12=BP12,+'Biyemas S.A.'!AY12+'Kandiko S.A'!AY12+'Rebisco S.A.'!AY12,"") | AZ12: =IF(A12="","",IF($AZ$6>0,+AY12-$AZ$6,)) | BA12: =IF(A12=BP12,+'Biyemas S.A.'!BA12+'Kandiko S.A'!BA12+'Rebisco S.A.'!BA12,"") | BB12: =IF(A12="","",IF(BA12>0,(C12-BA12)/BA12,100%)) | BC12: =IF(A12=BP12,+'Biyemas S.A.'!BC12+'Kandiko S.A'!BC12+'Rebisco S.A.'!BC12,"") | BD12: =IF(A12="","",IF(AN12=BC12,0,IF(BC12>0,(AN12-BC12)/BC12,1))) | BE12: =IF(A12="","",VLOOKUP(B12,'Datos Consolidados'!B14:BF51,53,0)) | BF12: =IF(A12="","",VLOOKUP(B12,'Datos Consolidados'!B14:BF51,54,0)) | BG12: =IF(A12="","",VLOOKUP(B12,'Datos Consolidados'!B14:BF51,55,0)) | BH12: =IF(A12="","",VLOOKUP(B12,'Datos Consolidados'!B14:BF51,51,0)) | BI12: =IF(A12="","",VLOOKUP(B12,'Datos Consolidados'!B14:BF51,52,0)) | BJ12: =IF(A12="","",+AV12/$BJ$6-1) | BK12: =IF(A12="","",+AD12/$BK$6-1) | BL12: =IF(A12="","",+AI12/$BL$6-1) | BM12: =IF(A12="","",AL12/$BM$6-1) | BN12: =+'Biyemas S.A.'!BN12 | BP12: =+'Biyemas S.A.'!BP12 -> Jue/Thu
A13: =IF(BP13='Datos Biyemas'!A15,'Datos Biyemas'!A15,"") | B13: =IF(BP13=A13,'Datos Biyemas'!B15,"") | C13: =IF(A13=BP13,+'Biyemas S.A.'!C13+'Kandiko S.A'!C13+'Rebisco S.A.'!C13,"") | D13: =IF(A13=BP13,+'Biyemas S.A.'!D13+'Kandiko S.A'!D13+'Rebisco S.A.'!D13,"") | E13: =IF(A13=BP13,+'Biyemas S.A.'!E13+'Kandiko S.A'!E13+'Rebisco S.A.'!E13,"") | F13: =IF(A13=BP13,+'Biyemas S.A.'!F13+'Kandiko S.A'!F13+'Rebisco S.A.'!F13,"") | G13: =IF(A13=BP13,+'Biyemas S.A.'!G13+'Kandiko S.A'!G13+'Rebisco S.A.'!G13,"") | H13: =IF(BP13=A13,IF(E13>0,+G13/E13,0),"") | I13: =IF(A13="","",IF(F13>0,+G13/F13,0)) | J13: =IF(A13="","",IF(G13>0,+G13/C13,0)) | K13: =IF(A13="","",IF(G13>0,+G13/D13,0)) | L13: =IF(A13=BP13,+'Biyemas S.A.'!L13+'Kandiko S.A'!L13+'Rebisco S.A.'!L13,"") | M13: =IF(A13=BP13,+'Biyemas S.A.'!M13+'Kandiko S.A'!M13+'Rebisco S.A.'!M13,"") | N13: =IF(A13=BP13,+'Biyemas S.A.'!N13+'Kandiko S.A'!N13+'Rebisco S.A.'!N13,"") | O13: =IF(A13=BP13,+'Biyemas S.A.'!O13+'Kandiko S.A'!O13+'Rebisco S.A.'!O13,"") | P13: =IF(A13="","",IF(M13>0,+O13/M13,0)) | Q13: =IF(A13="","",IF(N13>0,+O13/N13,0)) | R13: =IF(A13="","",IF(C13>0,+O13/C13,0)) | S13: =IF(A13="","",IF(C13>0,+O13/L13,0)) | T13: =IF(A13="","",IF(G13>0,(G13+O13)/(D13+L13),0)) | U13: =IF(A13="","",IF(D13>0,+L13+D13,0)) | V13: =IF(A13="","",VLOOKUP(B13,'Datos Biyemas'!B15:BB52,21,0)) | W13: =IF(A13="","",VLOOKUP(B13,'Datos Biyemas'!B15:BB52,22,0)) | X13: =IF(A13="","",VLOOKUP(B13,'Datos Biyemas'!B15:BB52,23,0)) | Y13: =IF(A13="","",VLOOKUP(B13,'Datos Biyemas'!B15:BB52,24,0)) | Z13: =IF(A13="","",IF(W13>0,+Y13/W13,0)) | AA13: =IF(A13="","",IF(X13>0,+Y13/X13,0)) | AB13: =IF(A13="","",IF(Y13>0,+Y13/K13,0)) | AC13: =IF(A13="","",IF(Y13>0,+Y13/V13,0)) | AD13: =IF(A13=BP13,+G13+O13+Y13,"") | AE13: =IF(A13=BP13,+'Biyemas S.A.'!AE13+'Kandiko S.A'!AE13+'Rebisco S.A.'!AE13,"") | AF13: =IF(A13="","",+AD13-AE13) | AG13: =IF(A13=BP13,+'Biyemas S.A.'!AG13+'Kandiko S.A'!AG13+'Rebisco S.A.'!AG13,"") | AH13: =IF(A13=BP13,+'Biyemas S.A.'!AH13+'Kandiko S.A'!AH13+'Rebisco S.A.'!AH13,"") | AI13: =IF(A13=BP13,+'Biyemas S.A.'!AI13+'Kandiko S.A'!AI13+'Rebisco S.A.'!AI13,"") | AJ13: =IF(A13="","",IF(AI13>0,+AI13/C13,0)) | AK13: =IF(A13="","",+G13+O13+AI13+Y13) | AL13: =IF(A13=BP13,+'Biyemas S.A.'!AL13+'Kandiko S.A'!AL13+'Rebisco S.A.'!AL13,"") | AM13: =IF(A13="","",IF(AL13>0,+AL13/C13,0)) | AN13: =IF(A13=BP13,+'Biyemas S.A.'!AN13+'Kandiko S.A'!AN13+'Rebisco S.A.'!AN13,"") | AO13: =IF(A13=BP13,+'Biyemas S.A.'!AO13+'Kandiko S.A'!AO13+'Rebisco S.A.'!AO13,"") | AP13: =IF(A13="","",IF(AN13>0,+AO13/AN13,0)) | AQ13: =IF(A13=BP13,+'Biyemas S.A.'!AQ13+'Kandiko S.A'!AQ13+'Rebisco S.A.'!AQ13,"") | AR13: =IF(A13=BP13,+'Biyemas S.A.'!AR13+'Kandiko S.A'!AR13+'Rebisco S.A.'!AR13,"") | AS13: =IF(A13=BP13,+'Biyemas S.A.'!AS13+'Kandiko S.A'!AS13+'Rebisco S.A.'!AS13,"") | AT13: =IF(A13=BP13,+'Biyemas S.A.'!AT13+'Kandiko S.A'!AT13+'Rebisco S.A.'!AT13,"") | AU13: =IFERROR('Biyemas S.A.'!AU13+'Kandiko S.A'!AU13+'Rebisco S.A.'!AU13,0) -> 0 | AV13: =IF(A13="","",+AD13+AI13+AL13+AO13) | AW13: =IF(A13="","",IF(AV13>0,+AV13/C13,0)) | AY13: =IF(A13=BP13,+'Biyemas S.A.'!AY13+'Kandiko S.A'!AY13+'Rebisco S.A.'!AY13,"") | AZ13: =IF(A13="","",IF($AZ$6>0,+AY13-$AZ$6,)) | BA13: =IF(A13=BP13,+'Biyemas S.A.'!BA13+'Kandiko S.A'!BA13+'Rebisco S.A.'!BA13,"") | BB13: =IF(A13="","",IF(BA13>0,(C13-BA13)/BA13,100%)) | BC13: =IF(A13=BP13,+'Biyemas S.A.'!BC13+'Kandiko S.A'!BC13+'Rebisco S.A.'!BC13,"") | BD13: =IF(A13="","",IF(AN13=BC13,0,IF(BC13>0,(AN13-BC13)/BC13,1))) | BE13: =IF(A13="","",VLOOKUP(B13,'Datos Consolidados'!B15:BF52,53,0)) | BF13: =IF(A13="","",VLOOKUP(B13,'Datos Consolidados'!B15:BF52,54,0)) | BG13: =IF(A13="","",VLOOKUP(B13,'Datos Consolidados'!B15:BF52,55,0)) | BH13: =IF(A13="","",VLOOKUP(B13,'Datos Consolidados'!B15:BF52,51,0)) | BI13: =IF(A13="","",VLOOKUP(B13,'Datos Consolidados'!B15:BF52,52,0)) | BJ13: =IF(A13="","",+AV13/$BJ$6-1) | BK13: =IF(A13="","",+AD13/$BK$6-1) | BL13: =IF(A13="","",+AI13/$BL$6-1) | BM13: =IF(A13="","",AL13/$BM$6-1) | BN13: =+'Biyemas S.A.'!BN13 | BP13: =+'Biyemas S.A.'!BP13 -> Vie/Fri
A14: =IF(BP14='Datos Biyemas'!A16,'Datos Biyemas'!A16,"") | B14: =IF(BP14=A14,'Datos Biyemas'!B16,"") | C14: =IF(A14=BP14,+'Biyemas S.A.'!C14+'Kandiko S.A'!C14+'Rebisco S.A.'!C14,"") | D14: =IF(A14=BP14,+'Biyemas S.A.'!D14+'Kandiko S.A'!D14+'Rebisco S.A.'!D14,"") | E14: =IF(A14=BP14,+'Biyemas S.A.'!E14+'Kandiko S.A'!E14+'Rebisco S.A.'!E14,"") | F14: =IF(A14=BP14,+'Biyemas S.A.'!F14+'Kandiko S.A'!F14+'Rebisco S.A.'!F14,"") | G14: =IF(A14=BP14,+'Biyemas S.A.'!G14+'Kandiko S.A'!G14+'Rebisco S.A.'!G14,"") | H14: =IF(BP14=A14,IF(E14>0,+G14/E14,0),"") | I14: =IF(A14="","",IF(F14>0,+G14/F14,0)) | J14: =IF(A14="","",IF(G14>0,+G14/C14,0)) | K14: =IF(A14="","",IF(G14>0,+G14/D14,0)) | L14: =IF(A14=BP14,+'Biyemas S.A.'!L14+'Kandiko S.A'!L14+'Rebisco S.A.'!L14,"") | M14: =IF(A14=BP14,+'Biyemas S.A.'!M14+'Kandiko S.A'!M14+'Rebisco S.A.'!M14,"") | N14: =IF(A14=BP14,+'Biyemas S.A.'!N14+'Kandiko S.A'!N14+'Rebisco S.A.'!N14,"") | O14: =IF(A14=BP14,+'Biyemas S.A.'!O14+'Kandiko S.A'!O14+'Rebisco S.A.'!O14,"") | P14: =IF(A14="","",IF(M14>0,+O14/M14,0)) | Q14: =IF(A14="","",IF(N14>0,+O14/N14,0)) | R14: =IF(A14="","",IF(C14>0,+O14/C14,0)) | S14: =IF(A14="","",IF(C14>0,+O14/L14,0)) | T14: =IF(A14="","",IF(G14>0,(G14+O14)/(D14+L14),0)) | U14: =IF(A14="","",IF(D14>0,+L14+D14,0)) | V14: =IF(A14="","",VLOOKUP(B14,'Datos Biyemas'!B16:BB53,21,0)) | W14: =IF(A14="","",VLOOKUP(B14,'Datos Biyemas'!B16:BB53,22,0)) | X14: =IF(A14="","",VLOOKUP(B14,'Datos Biyemas'!B16:BB53,23,0)) | Y14: =IF(A14="","",VLOOKUP(B14,'Datos Biyemas'!B16:BB53,24,0)) | Z14: =IF(A14="","",IF(W14>0,+Y14/W14,0)) | AA14: =IF(A14="","",IF(X14>0,+Y14/X14,0)) | AB14: =IF(A14="","",IF(Y14>0,+Y14/K14,0)) | AC14: =IF(A14="","",IF(Y14>0,+Y14/V14,0)) | AD14: =IF(A14=BP14,+G14+O14+Y14,"") | AE14: =IF(A14=BP14,+'Biyemas S.A.'!AE14+'Kandiko S.A'!AE14+'Rebisco S.A.'!AE14,"") | AF14: =IF(A14="","",+AD14-AE14) | AG14: =IF(A14=BP14,+'Biyemas S.A.'!AG14+'Kandiko S.A'!AG14+'Rebisco S.A.'!AG14,"") | AH14: =IF(A14=BP14,+'Biyemas S.A.'!AH14+'Kandiko S.A'!AH14+'Rebisco S.A.'!AH14,"") | AI14: =IF(A14=BP14,+'Biyemas S.A.'!AI14+'Kandiko S.A'!AI14+'Rebisco S.A.'!AI14,"") | AJ14: =IF(A14="","",IF(AI14>0,+AI14/C14,0)) | AK14: =IF(A14="","",+G14+O14+AI14+Y14) | AL14: =IF(A14=BP14,+'Biyemas S.A.'!AL14+'Kandiko S.A'!AL14+'Rebisco S.A.'!AL14,"") | AM14: =IF(A14="","",IF(AL14>0,+AL14/C14,0)) | AN14: =IF(A14=BP14,+'Biyemas S.A.'!AN14+'Kandiko S.A'!AN14+'Rebisco S.A.'!AN14,"") | AO14: =IF(A14=BP14,+'Biyemas S.A.'!AO14+'Kandiko S.A'!AO14+'Rebisco S.A.'!AO14,"") | AP14: =IF(A14="","",IF(AN14>0,+AO14/AN14,0)) | AQ14: =IF(A14=BP14,+'Biyemas S.A.'!AQ14+'Kandiko S.A'!AQ14+'Rebisco S.A.'!AQ14,"") | AR14: =IF(A14=BP14,+'Biyemas S.A.'!AR14+'Kandiko S.A'!AR14+'Rebisco S.A.'!AR14,"") | AS14: =IF(A14=BP14,+'Biyemas S.A.'!AS14+'Kandiko S.A'!AS14+'Rebisco S.A.'!AS14,"") | AT14: =IF(A14=BP14,+'Biyemas S.A.'!AT14+'Kandiko S.A'!AT14+'Rebisco S.A.'!AT14,"") | AU14: =IFERROR('Biyemas S.A.'!AU14+'Kandiko S.A'!AU14+'Rebisco S.A.'!AU14,0) -> 0 | AV14: =IF(A14="","",+AD14+AI14+AL14+AO14) | AW14: =IF(A14="","",IF(AV14>0,+AV14/C14,0)) | AY14: =IF(A14=BP14,+'Biyemas S.A.'!AY14+'Kandiko S.A'!AY14+'Rebisco S.A.'!AY14,"") | AZ14: =IF(A14="","",IF($AZ$6>0,+AY14-$AZ$6,)) | BA14: =IF(A14=BP14,+'Biyemas S.A.'!BA14+'Kandiko S.A'!BA14+'Rebisco S.A.'!BA14,"") | BB14: =IF(A14="","",IF(BA14>0,(C14-BA14)/BA14,100%)) | BC14: =IF(A14=BP14,+'Biyemas S.A.'!BC14+'Kandiko S.A'!BC14+'Rebisco S.A.'!BC14,"") | BD14: =IF(A14="","",IF(AN14=BC14,0,IF(BC14>0,(AN14-BC14)/BC14,1))) | BE14: =IF(A14="","",VLOOKUP(B14,'Datos Consolidados'!B16:BF53,53,0)) | BF14: =IF(A14="","",VLOOKUP(B14,'Datos Consolidados'!B16:BF53,54,0)) | BG14: =IF(A14="","",VLOOKUP(B14,'Datos Consolidados'!B16:BF53,55,0)) | BH14: =IF(A14="","",VLOOKUP(B14,'Datos Consolidados'!B16:BF53,51,0)) | BI14: =IF(A14="","",VLOOKUP(B14,'Datos Consolidados'!B16:BF53,52,0)) | BJ14: =IF(A14="","",+AV14/$BJ$6-1) | BK14: =IF(A14="","",+AD14/$BK$6-1) | BL14: =IF(A14="","",+AI14/$BL$6-1) | BM14: =IF(A14="","",AL14/$BM$6-1) | BN14: =+'Biyemas S.A.'!BN14 | BP14: =+'Biyemas S.A.'!BP14 -> Sab/Sat
A15: =IF(BP15='Datos Biyemas'!A17,'Datos Biyemas'!A17,"") | B15: =IF(BP15=A15,'Datos Biyemas'!B17,"") | C15: =IF(A15=BP15,+'Biyemas S.A.'!C15+'Kandiko S.A'!C15+'Rebisco S.A.'!C15,"") | D15: =IF(A15=BP15,+'Biyemas S.A.'!D15+'Kandiko S.A'!D15+'Rebisco S.A.'!D15,"") | E15: =IF(A15=BP15,+'Biyemas S.A.'!E15+'Kandiko S.A'!E15+'Rebisco S.A.'!E15,"") | F15: =IF(A15=BP15,+'Biyemas S.A.'!F15+'Kandiko S.A'!F15+'Rebisco S.A.'!F15,"") | G15: =IF(A15=BP15,+'Biyemas S.A.'!G15+'Kandiko S.A'!G15+'Rebisco S.A.'!G15,"") | H15: =IF(BP15=A15,IF(E15>0,+G15/E15,0),"") | I15: =IF(A15="","",IF(F15>0,+G15/F15,0)) | J15: =IF(A15="","",IF(G15>0,+G15/C15,0)) | K15: =IF(A15="","",IF(G15>0,+G15/D15,0)) | L15: =IF(A15=BP15,+'Biyemas S.A.'!L15+'Kandiko S.A'!L15+'Rebisco S.A.'!L15,"") | M15: =IF(A15=BP15,+'Biyemas S.A.'!M15+'Kandiko S.A'!M15+'Rebisco S.A.'!M15,"") | N15: =IF(A15=BP15,+'Biyemas S.A.'!N15+'Kandiko S.A'!N15+'Rebisco S.A.'!N15,"") | O15: =IF(A15=BP15,+'Biyemas S.A.'!O15+'Kandiko S.A'!O15+'Rebisco S.A.'!O15,"") | P15: =IF(A15="","",IF(M15>0,+O15/M15,0)) | Q15: =IF(A15="","",IF(N15>0,+O15/N15,0)) | R15: =IF(A15="","",IF(C15>0,+O15/C15,0)) | S15: =IF(A15="","",IF(C15>0,+O15/L15,0)) | T15: =IF(A15="","",IF(G15>0,(G15+O15)/(D15+L15),0)) | U15: =IF(A15="","",IF(D15>0,+L15+D15,0)) | V15: =IF(A15="","",VLOOKUP(B15,'Datos Biyemas'!B17:BB54,21,0)) | W15: =IF(A15="","",VLOOKUP(B15,'Datos Biyemas'!B17:BB54,22,0)) | X15: =IF(A15="","",VLOOKUP(B15,'Datos Biyemas'!B17:BB54,23,0)) | Y15: =IF(A15="","",VLOOKUP(B15,'Datos Biyemas'!B17:BB54,24,0)) | Z15: =IF(A15="","",IF(W15>0,+Y15/W15,0)) | AA15: =IF(A15="","",IF(X15>0,+Y15/X15,0)) | AB15: =IF(A15="","",IF(Y15>0,+Y15/K15,0)) | AC15: =IF(A15="","",IF(Y15>0,+Y15/V15,0)) | AD15: =IF(A15=BP15,+G15+O15+Y15,"") | AE15: =IF(A15=BP15,+'Biyemas S.A.'!AE15+'Kandiko S.A'!AE15+'Rebisco S.A.'!AE15,"") | AF15: =IF(A15="","",+AD15-AE15) | AG15: =IF(A15=BP15,+'Biyemas S.A.'!AG15+'Kandiko S.A'!AG15+'Rebisco S.A.'!AG15,"") | AH15: =IF(A15=BP15,+'Biyemas S.A.'!AH15+'Kandiko S.A'!AH15+'Rebisco S.A.'!AH15,"") | AI15: =IF(A15=BP15,+'Biyemas S.A.'!AI15+'Kandiko S.A'!AI15+'Rebisco S.A.'!AI15,"") | AJ15: =IF(A15="","",IF(AI15>0,+AI15/C15,0)) | AK15: =IF(A15="","",+G15+O15+AI15+Y15) | AL15: =IF(A15=BP15,+'Biyemas S.A.'!AL15+'Kandiko S.A'!AL15+'Rebisco S.A.'!AL15,"") | AM15: =IF(A15="","",IF(AL15>0,+AL15/C15,0)) | AN15: =IF(A15=BP15,+'Biyemas S.A.'!AN15+'Kandiko S.A'!AN15+'Rebisco S.A.'!AN15,"") | AO15: =IF(A15=BP15,+'Biyemas S.A.'!AO15+'Kandiko S.A'!AO15+'Rebisco S.A.'!AO15,"") | AP15: =IF(A15="","",IF(AN15>0,+AO15/AN15,0)) | AQ15: =IF(A15=BP15,+'Biyemas S.A.'!AQ15+'Kandiko S.A'!AQ15+'Rebisco S.A.'!AQ15,"") | AR15: =IF(A15=BP15,+'Biyemas S.A.'!AR15+'Kandiko S.A'!AR15+'Rebisco S.A.'!AR15,"") | AS15: =IF(A15=BP15,+'Biyemas S.A.'!AS15+'Kandiko S.A'!AS15+'Rebisco S.A.'!AS15,"") | AT15: =IF(A15=BP15,+'Biyemas S.A.'!AT15+'Kandiko S.A'!AT15+'Rebisco S.A.'!AT15,"") | AU15: =IFERROR('Biyemas S.A.'!AU15+'Kandiko S.A'!AU15+'Rebisco S.A.'!AU15,0) -> 0 | AV15: =IF(A15="","",+AD15+AI15+AL15+AO15) | AW15: =IF(A15="","",IF(AV15>0,+AV15/C15,0)) | AY15: =IF(A15=BP15,+'Biyemas S.A.'!AY15+'Kandiko S.A'!AY15+'Rebisco S.A.'!AY15,"") | AZ15: =IF(A15="","",IF($AZ$6>0,+AY15-$AZ$6,)) | BA15: =IF(A15=BP15,+'Biyemas S.A.'!BA15+'Kandiko S.A'!BA15+'Rebisco S.A.'!BA15,"") | BB15: =IF(A15="","",IF(BA15>0,(C15-BA15)/BA15,100%)) | BC15: =IF(A15=BP15,+'Biyemas S.A.'!BC15+'Kandiko S.A'!BC15+'Rebisco S.A.'!BC15,"") | BD15: =IF(A15="","",IF(AN15=BC15,0,IF(BC15>0,(AN15-BC15)/BC15,1))) | BE15: =IF(A15="","",VLOOKUP(B15,'Datos Consolidados'!B17:BF54,53,0)) | BF15: =IF(A15="","",VLOOKUP(B15,'Datos Consolidados'!B17:BF54,54,0)) | BG15: =IF(A15="","",VLOOKUP(B15,'Datos Consolidados'!B17:BF54,55,0)) | BH15: =IF(A15="","",VLOOKUP(B15,'Datos Consolidados'!B17:BF54,51,0)) | BI15: =IF(A15="","",VLOOKUP(B15,'Datos Consolidados'!B17:BF54,52,0)) | BJ15: =IF(A15="","",+AV15/$BJ$6-1) | BK15: =IF(A15="","",+AD15/$BK$6-1) | BL15: =IF(A15="","",+AI15/$BL$6-1) | BM15: =IF(A15="","",AL15/$BM$6-1) | BN15: =+'Biyemas S.A.'!BN15 | BP15: =+'Biyemas S.A.'!BP15 -> Dom/Sun
A16: =IF(BP16='Datos Biyemas'!A18,'Datos Biyemas'!A18,"") | B16: =IF(BP16=A16,'Datos Biyemas'!B18,"") | C16: =IF(A16=BP16,+'Biyemas S.A.'!C16+'Kandiko S.A'!C16+'Rebisco S.A.'!C16,"") | D16: =IF(A16=BP16,+'Biyemas S.A.'!D16+'Kandiko S.A'!D16+'Rebisco S.A.'!D16,"") | E16: =IF(A16=BP16,+'Biyemas S.A.'!E16+'Kandiko S.A'!E16+'Rebisco S.A.'!E16,"") | F16: =IF(A16=BP16,+'Biyemas S.A.'!F16+'Kandiko S.A'!F16+'Rebisco S.A.'!F16,"") | G16: =IF(A16=BP16,+'Biyemas S.A.'!G16+'Kandiko S.A'!G16+'Rebisco S.A.'!G16,"") | H16: =IF(BP16=A16,IF(E16>0,+G16/E16,0),"") | I16: =IF(A16="","",IF(F16>0,+G16/F16,0)) | J16: =IF(A16="","",IF(G16>0,+G16/C16,0)) | K16: =IF(A16="","",IF(G16>0,+G16/D16,0)) | L16: =IF(A16=BP16,+'Biyemas S.A.'!L16+'Kandiko S.A'!L16+'Rebisco S.A.'!L16,"") | M16: =IF(A16=BP16,+'Biyemas S.A.'!M16+'Kandiko S.A'!M16+'Rebisco S.A.'!M16,"") | N16: =IF(A16=BP16,+'Biyemas S.A.'!N16+'Kandiko S.A'!N16+'Rebisco S.A.'!N16,"") | O16: =IF(A16=BP16,+'Biyemas S.A.'!O16+'Kandiko S.A'!O16+'Rebisco S.A.'!O16,"") | P16: =IF(A16="","",IF(M16>0,+O16/M16,0)) | Q16: =IF(A16="","",IF(N16>0,+O16/N16,0)) | R16: =IF(A16="","",IF(C16>0,+O16/C16,0)) | S16: =IF(A16="","",IF(C16>0,+O16/L16,0)) | T16: =IF(A16="","",IF(G16>0,(G16+O16)/(D16+L16),0)) | U16: =IF(A16="","",IF(D16>0,+L16+D16,0)) | V16: =IF(A16="","",VLOOKUP(B16,'Datos Biyemas'!B18:BB55,21,0)) | W16: =IF(A16="","",VLOOKUP(B16,'Datos Biyemas'!B18:BB55,22,0)) | X16: =IF(A16="","",VLOOKUP(B16,'Datos Biyemas'!B18:BB55,23,0)) | Y16: =IF(A16="","",VLOOKUP(B16,'Datos Biyemas'!B18:BB55,24,0)) | Z16: =IF(A16="","",IF(W16>0,+Y16/W16,0)) | AA16: =IF(A16="","",IF(X16>0,+Y16/X16,0)) | AB16: =IF(A16="","",IF(Y16>0,+Y16/K16,0)) | AC16: =IF(A16="","",IF(Y16>0,+Y16/V16,0)) | AD16: =IF(A16=BP16,+G16+O16+Y16,"") | AE16: =IF(A16=BP16,+'Biyemas S.A.'!AE16+'Kandiko S.A'!AE16+'Rebisco S.A.'!AE16,"") | AF16: =IF(A16="","",+AD16-AE16) | AG16: =IF(A16=BP16,+'Biyemas S.A.'!AG16+'Kandiko S.A'!AG16+'Rebisco S.A.'!AG16,"") | AH16: =IF(A16=BP16,+'Biyemas S.A.'!AH16+'Kandiko S.A'!AH16+'Rebisco S.A.'!AH16,"") | AI16: =IF(A16=BP16,+'Biyemas S.A.'!AI16+'Kandiko S.A'!AI16+'Rebisco S.A.'!AI16,"") | AJ16: =IF(A16="","",IF(AI16>0,+AI16/C16,0)) | AK16: =IF(A16="","",+G16+O16+AI16+Y16) | AL16: =IF(A16=BP16,+'Biyemas S.A.'!AL16+'Kandiko S.A'!AL16+'Rebisco S.A.'!AL16,"") | AM16: =IF(A16="","",IF(AL16>0,+AL16/C16,0)) | AN16: =IF(A16=BP16,+'Biyemas S.A.'!AN16+'Kandiko S.A'!AN16+'Rebisco S.A.'!AN16,"") | AO16: =IF(A16=BP16,+'Biyemas S.A.'!AO16+'Kandiko S.A'!AO16+'Rebisco S.A.'!AO16,"") | AP16: =IF(A16="","",IF(AN16>0,+AO16/AN16,0)) | AQ16: =IF(A16=BP16,+'Biyemas S.A.'!AQ16+'Kandiko S.A'!AQ16+'Rebisco S.A.'!AQ16,"") | AR16: =IF(A16=BP16,+'Biyemas S.A.'!AR16+'Kandiko S.A'!AR16+'Rebisco S.A.'!AR16,"") | AS16: =IF(A16=BP16,+'Biyemas S.A.'!AS16+'Kandiko S.A'!AS16+'Rebisco S.A.'!AS16,"") | AT16: =IF(A16=BP16,+'Biyemas S.A.'!AT16+'Kandiko S.A'!AT16+'Rebisco S.A.'!AT16,"") | AU16: =IFERROR('Biyemas S.A.'!AU16+'Kandiko S.A'!AU16+'Rebisco S.A.'!AU16,0) -> 0 | AV16: =IF(A16="","",+AD16+AI16+AL16+AO16) | AW16: =IF(A16="","",IF(AV16>0,+AV16/C16,0)) | AY16: =IF(A16=BP16,+'Biyemas S.A.'!AY16+'Kandiko S.A'!AY16+'Rebisco S.A.'!AY16,"") | AZ16: =IF(A16="","",IF($AZ$6>0,+AY16-$AZ$6,)) | BA16: =IF(A16=BP16,+'Biyemas S.A.'!BA16+'Kandiko S.A'!BA16+'Rebisco S.A.'!BA16,"") | BB16: =IF(A16="","",IF(BA16>0,(C16-BA16)/BA16,100%)) | BC16: =IF(A16=BP16,+'Biyemas S.A.'!BC16+'Kandiko S.A'!BC16+'Rebisco S.A.'!BC16,"") | BD16: =IF(A16="","",IF(AN16=BC16,0,IF(BC16>0,(AN16-BC16)/BC16,1))) | BE16: =IF(A16="","",VLOOKUP(B16,'Datos Consolidados'!B18:BF55,53,0)) | BF16: =IF(A16="","",VLOOKUP(B16,'Datos Consolidados'!B18:BF55,54,0)) | BG16: =IF(A16="","",VLOOKUP(B16,'Datos Consolidados'!B18:BF55,55,0)) | BH16: =IF(A16="","",VLOOKUP(B16,'Datos Consolidados'!B18:BF55,51,0)) | BI16: =IF(A16="","",VLOOKUP(B16,'Datos Consolidados'!B18:BF55,52,0)) | BJ16: =IF(A16="","",+AV16/$BJ$6-1) | BK16: =IF(A16="","",+AD16/$BK$6-1) | BL16: =IF(A16="","",+AI16/$BL$6-1) | BM16: =IF(A16="","",AL16/$BM$6-1) | BN16: =+'Biyemas S.A.'!BN16 | BP16: =+'Biyemas S.A.'!BP16 -> Lun/Mon
A17: =IF(BP17='Datos Biyemas'!A19,'Datos Biyemas'!A19,"") | B17: =IF(BP17=A17,'Datos Biyemas'!B19,"") | C17: =IF(A17=BP17,+'Biyemas S.A.'!C17+'Kandiko S.A'!C17+'Rebisco S.A.'!C17,"") | D17: =IF(A17=BP17,+'Biyemas S.A.'!D17+'Kandiko S.A'!D17+'Rebisco S.A.'!D17,"") | E17: =IF(A17=BP17,+'Biyemas S.A.'!E17+'Kandiko S.A'!E17+'Rebisco S.A.'!E17,"") | F17: =IF(A17=BP17,+'Biyemas S.A.'!F17+'Kandiko S.A'!F17+'Rebisco S.A.'!F17,"") | G17: =IF(A17=BP17,+'Biyemas S.A.'!G17+'Kandiko S.A'!G17+'Rebisco S.A.'!G17,"") | H17: =IF(BP17=A17,IF(E17>0,+G17/E17,0),"") | I17: =IF(A17="","",IF(F17>0,+G17/F17,0)) | J17: =IF(A17="","",IF(G17>0,+G17/C17,0)) | K17: =IF(A17="","",IF(G17>0,+G17/D17,0)) | L17: =IF(A17=BP17,+'Biyemas S.A.'!L17+'Kandiko S.A'!L17+'Rebisco S.A.'!L17,"") | M17: =IF(A17=BP17,+'Biyemas S.A.'!M17+'Kandiko S.A'!M17+'Rebisco S.A.'!M17,"") | N17: =IF(A17=BP17,+'Biyemas S.A.'!N17+'Kandiko S.A'!N17+'Rebisco S.A.'!N17,"") | O17: =IF(A17=BP17,+'Biyemas S.A.'!O17+'Kandiko S.A'!O17+'Rebisco S.A.'!O17,"") | P17: =IF(A17="","",IF(M17>0,+O17/M17,0)) | Q17: =IF(A17="","",IF(N17>0,+O17/N17,0)) | R17: =IF(A17="","",IF(C17>0,+O17/C17,0)) | S17: =IF(A17="","",IF(C17>0,+O17/L17,0)) | T17: =IF(A17="","",IF(G17>0,(G17+O17)/(D17+L17),0)) | U17: =IF(A17="","",IF(D17>0,+L17+D17,0)) | V17: =IF(A17="","",VLOOKUP(B17,'Datos Biyemas'!B19:BB56,21,0)) | W17: =IF(A17="","",VLOOKUP(B17,'Datos Biyemas'!B19:BB56,22,0)) | X17: =IF(A17="","",VLOOKUP(B17,'Datos Biyemas'!B19:BB56,23,0)) | Y17: =IF(A17="","",VLOOKUP(B17,'Datos Biyemas'!B19:BB56,24,0)) | Z17: =IF(A17="","",IF(W17>0,+Y17/W17,0)) | AA17: =IF(A17="","",IF(X17>0,+Y17/X17,0)) | AB17: =IF(A17="","",IF(Y17>0,+Y17/K17,0)) | AC17: =IF(A17="","",IF(Y17>0,+Y17/V17,0)) | AD17: =IF(A17=BP17,+G17+O17+Y17,"") | AE17: =IF(A17=BP17,+'Biyemas S.A.'!AE17+'Kandiko S.A'!AE17+'Rebisco S.A.'!AE17,"") | AF17: =IF(A17="","",+AD17-AE17) | AG17: =IF(A17=BP17,+'Biyemas S.A.'!AG17+'Kandiko S.A'!AG17+'Rebisco S.A.'!AG17,"") | AH17: =IF(A17=BP17,+'Biyemas S.A.'!AH17+'Kandiko S.A'!AH17+'Rebisco S.A.'!AH17,"") | AI17: =IF(A17=BP17,+'Biyemas S.A.'!AI17+'Kandiko S.A'!AI17+'Rebisco S.A.'!AI17,"") | AJ17: =IF(A17="","",IF(AI17>0,+AI17/C17,0)) | AK17: =IF(A17="","",+G17+O17+AI17+Y17) | AL17: =IF(A17=BP17,+'Biyemas S.A.'!AL17+'Kandiko S.A'!AL17+'Rebisco S.A.'!AL17,"") | AM17: =IF(A17="","",IF(AL17>0,+AL17/C17,0)) | AN17: =IF(A17=BP17,+'Biyemas S.A.'!AN17+'Kandiko S.A'!AN17+'Rebisco S.A.'!AN17,"") | AO17: =IF(A17=BP17,+'Biyemas S.A.'!AO17+'Kandiko S.A'!AO17+'Rebisco S.A.'!AO17,"") | AP17: =IF(A17="","",IF(AN17>0,+AO17/AN17,0)) | AQ17: =IF(A17=BP17,+'Biyemas S.A.'!AQ17+'Kandiko S.A'!AQ17+'Rebisco S.A.'!AQ17,"") | AR17: =IF(A17=BP17,+'Biyemas S.A.'!AR17+'Kandiko S.A'!AR17+'Rebisco S.A.'!AR17,"") | AS17: =IF(A17=BP17,+'Biyemas S.A.'!AS17+'Kandiko S.A'!AS17+'Rebisco S.A.'!AS17,"") | AT17: =IF(A17=BP17,+'Biyemas S.A.'!AT17+'Kandiko S.A'!AT17+'Rebisco S.A.'!AT17,"") | AU17: =IFERROR('Biyemas S.A.'!AU17+'Kandiko S.A'!AU17+'Rebisco S.A.'!AU17,0) -> 0 | AV17: =IF(A17="","",+AD17+AI17+AL17+AO17) | AW17: =IF(A17="","",IF(AV17>0,+AV17/C17,0)) | AY17: =IF(A17=BP17,+'Biyemas S.A.'!AY17+'Kandiko S.A'!AY17+'Rebisco S.A.'!AY17,"") | AZ17: =IF(A17="","",IF($AZ$6>0,+AY17-$AZ$6,)) | BA17: =IF(A17=BP17,+'Biyemas S.A.'!BA17+'Kandiko S.A'!BA17+'Rebisco S.A.'!BA17,"") | BB17: =IF(A17="","",IF(BA17>0,(C17-BA17)/BA17,100%)) | BC17: =IF(A17=BP17,+'Biyemas S.A.'!BC17+'Kandiko S.A'!BC17+'Rebisco S.A.'!BC17,"") | BD17: =IF(A17="","",IF(AN17=BC17,0,IF(BC17>0,(AN17-BC17)/BC17,1))) | BE17: =IF(A17="","",VLOOKUP(B17,'Datos Consolidados'!B19:BF56,53,0)) | BF17: =IF(A17="","",VLOOKUP(B17,'Datos Consolidados'!B19:BF56,54,0)) | BG17: =IF(A17="","",VLOOKUP(B17,'Datos Consolidados'!B19:BF56,55,0)) | BH17: =IF(A17="","",VLOOKUP(B17,'Datos Consolidados'!B19:BF56,51,0)) | BI17: =IF(A17="","",VLOOKUP(B17,'Datos Consolidados'!B19:BF56,52,0)) | BJ17: =IF(A17="","",+AV17/$BJ$6-1) | BK17: =IF(A17="","",+AD17/$BK$6-1) | BL17: =IF(A17="","",+AI17/$BL$6-1) | BM17: =IF(A17="","",AL17/$BM$6-1) | BN17: =+'Biyemas S.A.'!BN17 | BP17: =+'Biyemas S.A.'!BP17 -> Mar/Tue
A18: =IF(BP18='Datos Biyemas'!A20,'Datos Biyemas'!A20,"") | B18: =IF(BP18=A18,'Datos Biyemas'!B20,"") | C18: =IF(A18=BP18,+'Biyemas S.A.'!C18+'Kandiko S.A'!C18+'Rebisco S.A.'!C18,"") | D18: =IF(A18=BP18,+'Biyemas S.A.'!D18+'Kandiko S.A'!D18+'Rebisco S.A.'!D18,"") | E18: =IF(A18=BP18,+'Biyemas S.A.'!E18+'Kandiko S.A'!E18+'Rebisco S.A.'!E18,"") | F18: =IF(A18=BP18,+'Biyemas S.A.'!F18+'Kandiko S.A'!F18+'Rebisco S.A.'!F18,"") | G18: =IF(A18=BP18,+'Biyemas S.A.'!G18+'Kandiko S.A'!G18+'Rebisco S.A.'!G18,"") | H18: =IF(BP18=A18,IF(E18>0,+G18/E18,0),"") | I18: =IF(A18="","",IF(F18>0,+G18/F18,0)) | J18: =IF(A18="","",IF(G18>0,+G18/C18,0)) | K18: =IF(A18="","",IF(G18>0,+G18/D18,0)) | L18: =IF(A18=BP18,+'Biyemas S.A.'!L18+'Kandiko S.A'!L18+'Rebisco S.A.'!L18,"") | M18: =IF(A18=BP18,+'Biyemas S.A.'!M18+'Kandiko S.A'!M18+'Rebisco S.A.'!M18,"") | N18: =IF(A18=BP18,+'Biyemas S.A.'!N18+'Kandiko S.A'!N18+'Rebisco S.A.'!N18,"") | O18: =IF(A18=BP18,+'Biyemas S.A.'!O18+'Kandiko S.A'!O18+'Rebisco S.A.'!O18,"") | P18: =IF(A18="","",IF(M18>0,+O18/M18,0)) | Q18: =IF(A18="","",IF(N18>0,+O18/N18,0)) | R18: =IF(A18="","",IF(C18>0,+O18/C18,0)) | S18: =IF(A18="","",IF(C18>0,+O18/L18,0)) | T18: =IF(A18="","",IF(G18>0,(G18+O18)/(D18+L18),0)) | U18: =IF(A18="","",IF(D18>0,+L18+D18,0)) | V18: =IF(A18="","",VLOOKUP(B18,'Datos Biyemas'!B20:BB57,21,0)) | W18: =IF(A18="","",VLOOKUP(B18,'Datos Biyemas'!B20:BB57,22,0)) | X18: =IF(A18="","",VLOOKUP(B18,'Datos Biyemas'!B20:BB57,23,0)) | Y18: =IF(A18="","",VLOOKUP(B18,'Datos Biyemas'!B20:BB57,24,0)) | Z18: =IF(A18="","",IF(W18>0,+Y18/W18,0)) | AA18: =IF(A18="","",IF(X18>0,+Y18/X18,0)) | AB18: =IF(A18="","",IF(Y18>0,+Y18/K18,0)) | AC18: =IF(A18="","",IF(Y18>0,+Y18/V18,0)) | AD18: =IF(A18=BP18,+G18+O18+Y18,"") | AE18: =IF(A18=BP18,+'Biyemas S.A.'!AE18+'Kandiko S.A'!AE18+'Rebisco S.A.'!AE18,"") | AF18: =IF(A18="","",+AD18-AE18) | AG18: =IF(A18=BP18,+'Biyemas S.A.'!AG18+'Kandiko S.A'!AG18+'Rebisco S.A.'!AG18,"") | AH18: =IF(A18=BP18,+'Biyemas S.A.'!AH18+'Kandiko S.A'!AH18+'Rebisco S.A.'!AH18,"") | AI18: =IF(A18=BP18,+'Biyemas S.A.'!AI18+'Kandiko S.A'!AI18+'Rebisco S.A.'!AI18,"") | AJ18: =IF(A18="","",IF(AI18>0,+AI18/C18,0)) | AK18: =IF(A18="","",+G18+O18+AI18+Y18) | AL18: =IF(A18=BP18,+'Biyemas S.A.'!AL18+'Kandiko S.A'!AL18+'Rebisco S.A.'!AL18,"") | AM18: =IF(A18="","",IF(AL18>0,+AL18/C18,0)) | AN18: =IF(A18=BP18,+'Biyemas S.A.'!AN18+'Kandiko S.A'!AN18+'Rebisco S.A.'!AN18,"") | AO18: =IF(A18=BP18,+'Biyemas S.A.'!AO18+'Kandiko S.A'!AO18+'Rebisco S.A.'!AO18,"") | AP18: =IF(A18="","",IF(AN18>0,+AO18/AN18,0)) | AQ18: =IF(A18=BP18,+'Biyemas S.A.'!AQ18+'Kandiko S.A'!AQ18+'Rebisco S.A.'!AQ18,"") | AR18: =IF(A18=BP18,+'Biyemas S.A.'!AR18+'Kandiko S.A'!AR18+'Rebisco S.A.'!AR18,"") | AS18: =IF(A18=BP18,+'Biyemas S.A.'!AS18+'Kandiko S.A'!AS18+'Rebisco S.A.'!AS18,"") | AT18: =IF(A18=BP18,+'Biyemas S.A.'!AT18+'Kandiko S.A'!AT18+'Rebisco S.A.'!AT18,"") | AU18: =IFERROR('Biyemas S.A.'!AU18+'Kandiko S.A'!AU18+'Rebisco S.A.'!AU18,0) -> 0 | AV18: =IF(A18="","",+AD18+AI18+AL18+AO18) | AW18: =IF(A18="","",IF(AV18>0,+AV18/C18,0)) | AY18: =IF(A18=BP18,+'Biyemas S.A.'!AY18+'Kandiko S.A'!AY18+'Rebisco S.A.'!AY18,"") | AZ18: =IF(A18="","",IF($AZ$6>0,+AY18-$AZ$6,)) | BA18: =IF(A18=BP18,+'Biyemas S.A.'!BA18+'Kandiko S.A'!BA18+'Rebisco S.A.'!BA18,"") | BB18: =IF(A18="","",IF(BA18>0,(C18-BA18)/BA18,100%)) | BC18: =IF(A18=BP18,+'Biyemas S.A.'!BC18+'Kandiko S.A'!BC18+'Rebisco S.A.'!BC18,"") | BD18: =IF(A18="","",IF(AN18=BC18,0,IF(BC18>0,(AN18-BC18)/BC18,1))) | BE18: =IF(A18="","",VLOOKUP(B18,'Datos Consolidados'!B20:BF57,53,0)) | BF18: =IF(A18="","",VLOOKUP(B18,'Datos Consolidados'!B20:BF57,54,0)) | BG18: =IF(A18="","",VLOOKUP(B18,'Datos Consolidados'!B20:BF57,55,0)) | BH18: =IF(A18="","",VLOOKUP(B18,'Datos Consolidados'!B20:BF57,51,0)) | BI18: =IF(A18="","",VLOOKUP(B18,'Datos Consolidados'!B20:BF57,52,0)) | BJ18: =IF(A18="","",+AV18/$BJ$6-1) | BK18: =IF(A18="","",+AD18/$BK$6-1) | BL18: =IF(A18="","",+AI18/$BL$6-1) | BM18: =IF(A18="","",AL18/$BM$6-1) | BN18: =+'Biyemas S.A.'!BN18 | BP18: =+'Biyemas S.A.'!BP18 -> Mie/Wed
A19: =IF(BP19='Datos Biyemas'!A21,'Datos Biyemas'!A21,"") | B19: =IF(BP19=A19,'Datos Biyemas'!B21,"") | C19: =IF(A19=BP19,+'Biyemas S.A.'!C19+'Kandiko S.A'!C19+'Rebisco S.A.'!C19,"") | D19: =IF(A19=BP19,+'Biyemas S.A.'!D19+'Kandiko S.A'!D19+'Rebisco S.A.'!D19,"") | E19: =IF(A19=BP19,+'Biyemas S.A.'!E19+'Kandiko S.A'!E19+'Rebisco S.A.'!E19,"") | F19: =IF(A19=BP19,+'Biyemas S.A.'!F19+'Kandiko S.A'!F19+'Rebisco S.A.'!F19,"") | G19: =IF(A19=BP19,+'Biyemas S.A.'!G19+'Kandiko S.A'!G19+'Rebisco S.A.'!G19,"") | H19: =IF(BP19=A19,IF(E19>0,+G19/E19,0),"") | I19: =IF(A19="","",IF(F19>0,+G19/F19,0)) | J19: =IF(A19="","",IF(G19>0,+G19/C19,0)) | K19: =IF(A19="","",IF(G19>0,+G19/D19,0)) | L19: =IF(A19=BP19,+'Biyemas S.A.'!L19+'Kandiko S.A'!L19+'Rebisco S.A.'!L19,"") | M19: =IF(A19=BP19,+'Biyemas S.A.'!M19+'Kandiko S.A'!M19+'Rebisco S.A.'!M19,"") | N19: =IF(A19=BP19,+'Biyemas S.A.'!N19+'Kandiko S.A'!N19+'Rebisco S.A.'!N19,"") | O19: =IF(A19=BP19,+'Biyemas S.A.'!O19+'Kandiko S.A'!O19+'Rebisco S.A.'!O19,"") | P19: =IF(A19="","",IF(M19>0,+O19/M19,0)) | Q19: =IF(A19="","",IF(N19>0,+O19/N19,0)) | R19: =IF(A19="","",IF(C19>0,+O19/C19,0)) | S19: =IF(A19="","",IF(C19>0,+O19/L19,0)) | T19: =IF(A19="","",IF(G19>0,(G19+O19)/(D19+L19),0)) | U19: =IF(A19="","",IF(D19>0,+L19+D19,0)) | V19: =IF(A19="","",VLOOKUP(B19,'Datos Biyemas'!B21:BB58,21,0)) | W19: =IF(A19="","",VLOOKUP(B19,'Datos Biyemas'!B21:BB58,22,0)) | X19: =IF(A19="","",VLOOKUP(B19,'Datos Biyemas'!B21:BB58,23,0)) | Y19: =IF(A19="","",VLOOKUP(B19,'Datos Biyemas'!B21:BB58,24,0)) | Z19: =IF(A19="","",IF(W19>0,+Y19/W19,0)) | AA19: =IF(A19="","",IF(X19>0,+Y19/X19,0)) | AB19: =IF(A19="","",IF(Y19>0,+Y19/K19,0)) | AC19: =IF(A19="","",IF(Y19>0,+Y19/V19,0)) | AD19: =IF(A19=BP19,+G19+O19+Y19,"") | AE19: =IF(A19=BP19,+'Biyemas S.A.'!AE19+'Kandiko S.A'!AE19+'Rebisco S.A.'!AE19,"") | AF19: =IF(A19="","",+AD19-AE19) | AG19: =IF(A19=BP19,+'Biyemas S.A.'!AG19+'Kandiko S.A'!AG19+'Rebisco S.A.'!AG19,"") | AH19: =IF(A19=BP19,+'Biyemas S.A.'!AH19+'Kandiko S.A'!AH19+'Rebisco S.A.'!AH19,"") | AI19: =IF(A19=BP19,+'Biyemas S.A.'!AI19+'Kandiko S.A'!AI19+'Rebisco S.A.'!AI19,"") | AJ19: =IF(A19="","",IF(AI19>0,+AI19/C19,0)) | AK19: =IF(A19="","",+G19+O19+AI19+Y19) | AL19: =IF(A19=BP19,+'Biyemas S.A.'!AL19+'Kandiko S.A'!AL19+'Rebisco S.A.'!AL19,"") | AM19: =IF(A19="","",IF(AL19>0,+AL19/C19,0)) | AN19: =IF(A19=BP19,+'Biyemas S.A.'!AN19+'Kandiko S.A'!AN19+'Rebisco S.A.'!AN19,"") | AO19: =IF(A19=BP19,+'Biyemas S.A.'!AO19+'Kandiko S.A'!AO19+'Rebisco S.A.'!AO19,"") | AP19: =IF(A19="","",IF(AN19>0,+AO19/AN19,0)) | AQ19: =IF(A19=BP19,+'Biyemas S.A.'!AQ19+'Kandiko S.A'!AQ19+'Rebisco S.A.'!AQ19,"") | AR19: =IF(A19=BP19,+'Biyemas S.A.'!AR19+'Kandiko S.A'!AR19+'Rebisco S.A.'!AR19,"") | AS19: =IF(A19=BP19,+'Biyemas S.A.'!AS19+'Kandiko S.A'!AS19+'Rebisco S.A.'!AS19,"") | AT19: =IF(A19=BP19,+'Biyemas S.A.'!AT19+'Kandiko S.A'!AT19+'Rebisco S.A.'!AT19,"") | AU19: =IFERROR('Biyemas S.A.'!AU19+'Kandiko S.A'!AU19+'Rebisco S.A.'!AU19,0) -> 0 | AV19: =IF(A19="","",+AD19+AI19+AL19+AO19) | AW19: =IF(A19="","",IF(AV19>0,+AV19/C19,0)) | AY19: =IF(A19=BP19,+'Biyemas S.A.'!AY19+'Kandiko S.A'!AY19+'Rebisco S.A.'!AY19,"") | AZ19: =IF(A19="","",IF($AZ$6>0,+AY19-$AZ$6,)) | BA19: =IF(A19=BP19,+'Biyemas S.A.'!BA19+'Kandiko S.A'!BA19+'Rebisco S.A.'!BA19,"") | BB19: =IF(A19="","",IF(BA19>0,(C19-BA19)/BA19,100%)) | BC19: =IF(A19=BP19,+'Biyemas S.A.'!BC19+'Kandiko S.A'!BC19+'Rebisco S.A.'!BC19,"") | BD19: =IF(A19="","",IF(AN19=BC19,0,IF(BC19>0,(AN19-BC19)/BC19,1))) | BE19: =IF(A19="","",VLOOKUP(B19,'Datos Consolidados'!B21:BF58,53,0)) | BF19: =IF(A19="","",VLOOKUP(B19,'Datos Consolidados'!B21:BF58,54,0)) | BG19: =IF(A19="","",VLOOKUP(B19,'Datos Consolidados'!B21:BF58,55,0)) | BH19: =IF(A19="","",VLOOKUP(B19,'Datos Consolidados'!B21:BF58,51,0)) | BI19: =IF(A19="","",VLOOKUP(B19,'Datos Consolidados'!B21:BF58,52,0)) | BJ19: =IF(A19="","",+AV19/$BJ$6-1) | BK19: =IF(A19="","",+AD19/$BK$6-1) | BL19: =IF(A19="","",+AI19/$BL$6-1) | BM19: =IF(A19="","",AL19/$BM$6-1) | BN19: =+'Biyemas S.A.'!BN19 | BP19: =+'Biyemas S.A.'!BP19 -> Jue/Thu
... A37: =IF(BP37='Datos Biyemas'!A39,'Datos Biyemas'!A39,"") | B37: =IF(BP37=A37,'Datos Biyemas'!B39,"") | C37: =IF(A37=BP37,+'Biyemas S.A.'!C37+'Kandiko S.A'!C37+'Rebisco S.A.'!C37,"") | D37: =IF(A37=BP37,+'Biyemas S.A.'!D37+'Kandiko S.A'!D37+'Rebisco S.A.'!D37,"") | E37: =IF(A37=BP37,+'Biyemas S.A.'!E37+'Kandiko S.A'!E37+'Rebisco S.A.'!E37,"") | F37: =IF(A37=BP37,+'Biyemas S.A.'!F37+'Kandiko S.A'!F37+'Rebisco S.A.'!F37,"") | G37: =IF(A37=BP37,+'Biyemas S.A.'!G37+'Kandiko S.A'!G37+'Rebisco S.A.'!G37,"") | H37: =IF(BP37=A37,IF(E37>0,+G37/E37,0),"") | I37: =IF(A37="","",IF(F37>0,+G37/F37,0)) | J37: =IF(A37="","",IF(G37>0,+G37/C37,0)) | K37: =IF(A37="","",IF(G37>0,+G37/D37,0)) | L37: =IF(A37=BP37,+'Biyemas S.A.'!L37+'Kandiko S.A'!L37+'Rebisco S.A.'!L37,"") | M37: =IF(A37=BP37,+'Biyemas S.A.'!M37+'Kandiko S.A'!M37+'Rebisco S.A.'!M37,"") | N37: =IF(A37=BP37,+'Biyemas S.A.'!N37+'Kandiko S.A'!N37+'Rebisco S.A.'!N37,"") | O37: =IF(A37=BP37,+'Biyemas S.A.'!O37+'Kandiko S.A'!O37+'Rebisco S.A.'!O37,"") | P37: =IF(A37="","",IF(M37>0,+O37/M37,0)) | Q37: =IF(A37="","",IF(N37>0,+O37/N37,0)) | R37: =IF(A37="","",IF(C37>0,+O37/C37,0)) | S37: =IF(A37="","",IF(C37>0,+O37/L37,0)) | T37: =IF(A37="","",IF(G37>0,(G37+O37)/(D37+L37),0)) | U37: =IF(A37="","",IF(D37>0,+L37+D37,0)) | V37: =IF(A37="","",VLOOKUP(B37,'Datos Biyemas'!B39:BB76,21,0)) | W37: =IF(A37="","",VLOOKUP(B37,'Datos Biyemas'!B39:BB76,22,0)) | X37: =IF(A37="","",VLOOKUP(B37,'Datos Biyemas'!B39:BB76,23,0)) | Y37: =IF(A37="","",VLOOKUP(B37,'Datos Biyemas'!B39:BB76,24,0)) | Z37: =IF(A37="","",IF(W37>0,+Y37/W37,0)) | AA37: =IF(A37="","",IF(X37>0,+Y37/X37,0)) | AB37: =IF(A37="","",IF(Y37>0,+Y37/K37,0)) | AC37: =IF(A37="","",IF(Y37>0,+Y37/V37,0)) | AD37: =IF(A37=BP37,+G37+O37+Y37,"") | AE37: =IF(A37=BP37,+'Biyemas S.A.'!AE37+'Kandiko S.A'!AE37+'Rebisco S.A.'!AE37,"") | AF37: =IF(A37="","",+AD37-AE37) | AG37: =IF(A37=BP37,+'Biyemas S.A.'!AG37+'Kandiko S.A'!AG37+'Rebisco S.A.'!AG37,"") | AH37: =IF(A37=BP37,+'Biyemas S.A.'!AH37+'Kandiko S.A'!AH37+'Rebisco S.A.'!AH37,"") | AI37: =IF(A37=BP37,+'Biyemas S.A.'!AI37+'Kandiko S.A'!AI37+'Rebisco S.A.'!AI37,"") | AJ37: =IF(A37="","",IF(AI37>0,+AI37/C37,0)) | AK37: =IF(A37="","",+G37+O37+AI37+Y37) | AL37: =IF(A37=BP37,+'Biyemas S.A.'!AL37+'Kandiko S.A'!AL37+'Rebisco S.A.'!AL37,"") | AM37: =IF(A37="","",IF(AL37>0,+AL37/C37,0)) | AN37: =IF(A37=BP37,+'Biyemas S.A.'!AN37+'Kandiko S.A'!AN37+'Rebisco S.A.'!AN37,"") | AO37: =IF(A37=BP37,+'Biyemas S.A.'!AO37+'Kandiko S.A'!AO37+'Rebisco S.A.'!AO37,"") | AP37: =IF(A37="","",IF(AN37>0,+AO37/AN37,0)) | AQ37: =IF(A37=BP37,+'Biyemas S.A.'!AQ37+'Kandiko S.A'!AQ37+'Rebisco S.A.'!AQ37,"") | AR37: =IF(A37=BP37,+'Biyemas S.A.'!AR37+'Kandiko S.A'!AR37+'Rebisco S.A.'!AR37,"") | AS37: =IF(A37=BP37,+'Biyemas S.A.'!AS37+'Kandiko S.A'!AS37+'Rebisco S.A.'!AS37,"") | AT37: =IF(A37=BP37,+'Biyemas S.A.'!AT37+'Kandiko S.A'!AT37+'Rebisco S.A.'!AT37,"") | AU37: =IFERROR('Biyemas S.A.'!AU37+'Kandiko S.A'!AU37+'Rebisco S.A.'!AU37,0) -> 0 | AV37: =IF(A37="","",+AD37+AI37+AL37+AO37) | AW37: =IF(A37="","",IF(AV37>0,+AV37/C37,0)) | AY37: =IF(A37=BP37,+'Biyemas S.A.'!AY37+'Kandiko S.A'!AY37+'Rebisco S.A.'!AY37,"") | AZ37: =IF(A37="","",IF($AZ$6>0,+AY37-$AZ$6,)) | BA37: =IF(A37=BP37,+'Biyemas S.A.'!BA37+'Kandiko S.A'!BA37+'Rebisco S.A.'!BA37,"") | BB37: =IF(A37="","",IF(BA37>0,(C37-BA37)/BA37,100%)) | BC37: =IF(A37=BP37,+'Biyemas S.A.'!BC37+'Kandiko S.A'!BC37+'Rebisco S.A.'!BC37,"") | BD37: =IF(A37="","",IF(AN37=BC37,0,IF(BC37>0,(AN37-BC37)/BC37,1))) | BE37: =IF(A37="","",VLOOKUP(B37,'Datos Consolidados'!B39:BF76,53,0)) | BF37: =IF(A37="","",VLOOKUP(B37,'Datos Consolidados'!B39:BF76,54,0)) | BG37: =IF(A37="","",VLOOKUP(B37,'Datos Consolidados'!B39:BF76,55,0)) | BH37: =IF(A37="","",VLOOKUP(B37,'Datos Consolidados'!B39:BF76,51,0)) | BI37: =IF(A37="","",VLOOKUP(B37,'Datos Consolidados'!B39:BF76,52,0)) | BJ37: =IF(A37="","",+AV37/$BJ$6-1) | BK37: =IF(A37="","",+AD37/$BK$6-1) | BL37: =IF(A37="","",+AI37/$BL$6-1) | BM37: =IF(A37="","",AL37/$BM$6-1) | BN37: =+'Biyemas S.A.'!BN37 | BP37: =+'Biyemas S.A.'!BP37 -> Lun/Mon
AU38: =IF(B38=BP38,+'Biyemas S.A.'!AU38+'Kandiko S.A'!AU38+'Rebisco S.A.'!AU38,"") -> 0 | AZ38: =IF(A38="","",IF($AZ$6>0,+AY38-$AZ$6,)) | BB38: =IF(A38="","",IF(BA38>0,(C38-BA38)/BA38,100%)) | BE38: =IF(A38="","",VLOOKUP(B38,'Datos Consolidados'!B40:BF77,53,0)) | BF38: =IF(A38="","",VLOOKUP(B38,'Datos Consolidados'!B40:BF77,54,0)) | BG38: =IF(A38="","",VLOOKUP(B38,'Datos Consolidados'!B40:BF77,55,0)) | BH38: =IF(A38="","",VLOOKUP(B38,'Datos Consolidados'!B40:BF77,51,0)) | BI38: =IF(A38="","",VLOOKUP(B38,'Datos Consolidados'!B40:BF77,52,0))
A39: Total final | C39: =SUM(C7:C38) -> 0 | E39: =SUM(E7:E38) -> 0 | F39: =SUM(F7:F38) -> 0 | G39: =SUM(G7:G38) -> 0 | M39: =SUM(M7:M38) -> 0 | N39: =SUM(N7:N38) -> 0 | O39: =SUM(O7:O38) -> 0 | W39: =SUM(W7:W38) -> 0 | X39: =SUM(X7:X38) -> 0 | Y39: =SUM(Y7:Y38) -> 0 | AD39: =SUM(AD7:AD38) -> 0 | AE39: =SUM(AE7:AE38) -> 0 | AF39: =SUM(AF7:AF38) -> 0 | AG39: =SUM(AG7:AG38) -> 0 | AH39: =SUM(AH7:AH38) -> 0 | AI39: =SUM(AI7:AI38) -> 0 | AK39: =SUM(AK7:AK38) -> 0 | AL39: =SUM(AL7:AL38) -> 0 | AN39: =SUM(AN7:AN38) -> 0 | AO39: =SUM(AO7:AO38) -> 0 | AQ39: =SUM(AQ7:AQ38) -> 0 | AR39: =SUM(AR7:AR38) -> 0 | AS39: =SUM(AS7:AS38) -> 0 | AT39: =SUM(AT7:AT38) -> 0 | AV39: =SUM(AV7:AV38) -> 0 | AY39: =SUM(AY7:AY38)/COUNT(AY7:AY38) -> #DIV/0! | AZ39: =AY39-AZ6 -> #DIV/0! | BA39: =SUM(BA7:BA38) -> 0 | BB39: =IF($AK39>0,(C39-($BA39))/($BA$39),) -> 0 | BC39: =SUM(BC7:BC38) -> 0 | BD39: =IF($BC39>0,(AN39-($BC39))/($BC$39),IF(AN39>0,1)) -> FALSE | BE39: =VLOOKUP("Total final",'Datos Consolidados'!A9:BF142,54,0) -> #N/A | BF39: =VLOOKUP("Total final",'Datos Consolidados'!A9:BF142,55,0) -> #N/A | BG39: =VLOOKUP("Total final",'Datos Consolidados'!A9:BF142,56,0) -> #N/A | BH39: =VLOOKUP("Total final",'Datos Consolidados'!A9:BF142,52,0) -> #N/A | BI39: =+'Biyemas S.A.'!BI39 -> #N/A | BJ39: =+BJ40/BJ6-1 -> #N/A | BK39: =+BK40/BK6-1 -> #N/A | BL39: =+BL40/BL6-1 -> #N/A | BM39: =+BM40/BM6-1 -> #N/A | BN39: =+'Biyemas S.A.'!BN39 -> #N/A
