Workbook

Sheet Saldos
A1: codigo | B1: sociedad | C1: banco | D1: moneda | E1: tipo_cuenta | F1: concepto | G1: saldo_dia | H1: 46235 | I1: 46236 | J1: 46237 | K1: 46238 | L1: 46239 | M1: 46240 | N1: 46241 | O1: 46242 | P1: 46243 | Q1: 46244 | R1: 46245 | S1: 46246 | T1: 46247 | U1: 46248 | V1: 46249 | W1: 46250 | X1: 46251 | Y1: 46252 | Z1: 46253 | AA1: 46254 | AB1: 46255 | AC1: 46256 | AD1: 46257 | AE1: 46258 | AF1: 46259 | AG1: 46260 | AH1: 46261 | AI1: 46262 | AJ1: 46263 | AK1: 46264 | AL1: 46265
A2: BIY|MACRO|ARS|CC | B2: BIY | C2: MACRO | D2: ARS | E2: CC | F2: 1) PESOS (CC) | G2: =IFERROR(INDEX(H2:AL2,MATCH(Resumen!$E$1,H$1:AL$1,0)),0) | H2: -56288018 | I2: -56288018 | J2: 27202569 | K2: -5.8979353e+08 | L2: -5.4521001e+08 | M2: -3.9090648e+08 | N2: -4.7966385e+08 | O2: -4.7966385e+08 | P2: -4.7966385e+08 | Q2: -3.490023e+08 | R2: -8.8340077e+08 | S2: -9.5264849e+08 | T2: -7.6321248e+08 | U2: -7.6424123e+08 | V2: -7.6424123e+08 | W2: -7.6424123e+08 | X2: -8.5035631e+08 | Y2: -8.5035631e+08 | Z2: -8.8689709e+08 | AA2: -7.804563e+08 | AB2: -7.4498575e+08 | AC2: -7.4498575e+08 | AD2: -7.4498575e+08 | AE2: -5.4250756e+08 | AF2: -5.3247895e+08 | AG2: -4.684265e+08 | AH2: -2.8289046e+08 | AI2: -2.2386262e+08 | AJ2: -2.2386262e+08 | AK2: -2.2386262e+08 | AL2: -1.4609713e+08
A3: BIY|MACRO|ARS|TRANSITO | B3: BIY | C3: MACRO | D3: ARS | E3: TRANSITO | F3: Depósitos en Tránsito | G3: =IFERROR(INDEX(H3:AL3,MATCH(Resumen!$E$1,H$1:AL$1,0)),0) | H3: 0 | I3: 0 | J3: 0 | K3: 0 | L3: 0 | M3: 0 | N3: 0 | O3: 0 | P3: 0 | Q3: 0 | R3: 0 | S3: 0 | T3: 0 | U3: 0 | V3: 0 | W3: 0 | X3: 0 | Y3: 0 | Z3: 0 | AA3: 0 | AB3: 0 | AC3: 0 | AD3: 0 | AE3: 0 | AF3: 0 | AG3: 0 | AH3: 0 | AI3: 0 | AJ3: 0 | AK3: 0 | AL3: 0
A4: BIY|MACRO|USD|CC | B4: BIY | C4: MACRO | D4: USD | E4: CC | F4: 2) DOLARES (CC) | G4: =IFERROR(INDEX(H4:AL4,MATCH(Resumen!$E$1,H$1:AL$1,0)),0) | H4: 45197.68 | I4: 45197.68 | J4: 45197.68 | K4: 45197.68 | L4: 45197.68 | M4: 45197.68 | N4: 45197.68 | O4: 45197.68 | P4: 45197.68 | Q4: 45197.68 | R4: 45197.68 | S4: 45197.68 | T4: 45197.68 | U4: 45197.68 | V4: 45197.68 | W4: 45197.68 | X4: 45197.68 | Y4: 45197.68 | Z4: 45197.68 | AA4: 45197.68 | AB4: 45197.68 | AC4: 45197.68 | AD4: 45197.68 | AE4: 45197.68 | AF4: 45197.68 | AG4: 45197.68 | AH4: 45197.68 | AI4: 63888.17 | AJ4: 63888.17 | AK4: 63888.17 | AL4: 63856.78
A5: BIY|MACRO|USD|TRANSITO | B5: BIY | C5: MACRO | D5: USD | E5: TRANSITO | F5: Depósitos en Tránsito | G5: =IFERROR(INDEX(H5:AL5,MATCH(Resumen!$E$1,H$1:AL$1,0)),0) | H5: 0 | I5: 0 | J5: 0 | K5: 0 | L5: 0 | M5: 0 | N5: 0 | O5: 0 | P5: 0 | Q5: 0 | R5: 0 | S5: 0 | T5: 0 | U5: 0 | V5: 0 | W5: 0 | X5: 0 | Y5: 0 | Z5: 0 | AA5: 0 | AB5: 0 | AC5: 0 | AD5: 0 | AE5: 0 | AF5: 0 | AG5: 0 | AH5: 0 | AI5: 0 | AJ5: 0 | AK5: 0 | AL5: 0
A6: BIY|ITAU|ARS|CC | B6: BIY | C6: ITAU | D6: ARS | E6: CC | F6: 1) PESOS (CC) | G6: =IFERROR(INDEX(H6:AL6,MATCH(Resumen!$E$1,H$1:AL$1,0)),0) | H6: 13184911 | I6: 13184911 | J6: 10239674 | K6: 11329986 | L6: 3418663.9 | M6: 27131952 | N6: 11542871 | O6: 11542871 | P6: 11542871 | Q6: 6576873.7 | R6: 8799580.1 | S6: 6954585.3 | T6: 17038000 | U6: 15301649 | V6: 15301649 | W6: 15301649 | X6: 6272237.5 | Y6: 6272237.5 | Z6: 27194430 | AA6: 9147306 | AB6: 6906398.1 | AC6: 6906398.1 | AD6: 6906398.1 | AE6: 16123848 | AF6: 11138595 | AG6: 10843419 | AH6: 31082146 | AI6: 13119548 | AJ6: 13119548 | AK6: 13119548 | AL6: 41966137
A7: BIY|ITAU|ARS|TRANSITO | B7: BIY | C7: ITAU | D7: ARS | E7: TRANSITO | F7: Depósitos en Tránsito | G7: =IFERROR(INDEX(H7:AL7,MATCH(Resumen!$E$1,H$1:AL$1,0)),0) | H7: 0 | I7: 0 | J7: 0 | K7: 0 | L7: 0 | M7: 0 | N7: 0 | O7: 0 | P7: 0 | Q7: 0 | R7: 0 | S7: 0 | T7: 0 | U7: 0 | V7: 0 | W7: 0 | X7: 0 | Y7: 0 | Z7: 0 | AA7: 0 | AB7: 0 | AC7: 0 | AD7: 0 | AE7: 0 | AF7: 0 | AG7: 0 | AH7: 0 | AI7: 0 | AJ7: 0 | AK7: 0 | AL7: 0
A8: BIY|ITAU|ARS|AVELLANEDA | B8: BIY | C8: ITAU | D8: ARS | E8: AVELLANEDA | F8: 1) PESOS (AVELLANEDA) | G8: =IFERROR(INDEX(H8:AL8,MATCH(Resumen!$E$1,H$1:AL$1,0)),0) | H8: 0 | I8: 0 | J8: 0 | K8: 0 | L8: 0 | M8: 0 | N8: 0 | O8: 0 | P8: 0 | Q8: 0 | R8: 0 | S8: 0 | T8: 0 | U8: 0 | V8: 0 | W8: 0 | X8: 0 | Y8: 0 | Z8: 0 | AA8: 0 | AB8: 0 | AC8: 0 | AD8: 0 | AE8: 0 | AF8: 0 | AG8: 0 | AH8: 0 | AI8: 0 | AJ8: 0 | AK8: 0 | AL8: 0
A9: BIY|ITAU|USD|CC | B9: BIY | C9: ITAU | D9: USD | E9: CC | F9: 2) DOLARES (CC) | G9: =IFERROR(INDEX(H9:AL9,MATCH(Resumen!$E$1,H$1:AL$1,0)),0) | H9: 0 | I9: 0 | J9: 0 | K9: 0 | L9: 0 | M9: 0 | N9: 0 | O9: 0 | P9: 0 | Q9: 0 | R9: 0 | S9: 0 | T9: 0 | U9: 0 | V9: 0 | W9: 0 | X9: 0 | Y9: 0 | Z9: 0 | AA9: 0 | AB9: 0 | AC9: 0 | AD9: 0 | AE9: 0 | AF9: 0 | AG9: 0 | AH9: 0 | AI9: 0 | AJ9: 0 | AK9: 0 | AL9: 0
A10: BIY|ITAU|USD|TRANSITO | B10: BIY | C10: ITAU | D10: USD | E10: TRANSITO | F10: Depósitos en Tránsito | G10: =IFERROR(INDEX(H10:AL10,MATCH(Resumen!$E$1,H$1:AL$1,0)),0) | H10: 0 | I10: 0 | J10: 0 | K10: 0 | L10: 0 | M10: 0 | N10: 0 | O10: 0 | P10: 0 | Q10: 0 | R10: 0 | S10: 0 | T10: 0 | U10: 0 | V10: 0 | W10: 0 | X10: 0 | Y10: 0 | Z10: 0 | AA10: 0 | AB10: 0 | AC10: 0 | AD10: 0 | AE10: 0 | AF10: 0 | AG10: 0 | AH10: 0 | AI10: 0 | AJ10: 0 | AK10: 0 | AL10: 0
A11: BIY|FRANCES|ARS|CC | B11: BIY | C11: FRANCES | D11: ARS | E11: CC | F11: 1) PESOS | G11: =IFERROR(INDEX(H11:AL11,MATCH(Resumen!$E$1,H$1:AL$1,0)),0) | H11: 224995.26 | I11: 224995.26 | J11: 224995.26 | K11: 80435.26 | L11: 79567.91 | M11: 79567.91 | N11: 79567.91 | O11: 79567.91 | P11: 79567.91 | Q11: 79567.91 | R11: 79567.91 | S11: 79567.91 | T11: 79567.91 | U11: 79567.91 | V11: 79567.91 | W11: 79567.91 | X11: 79567.91 | Y11: 79567.91 | Z11: 79567.91 | AA11: 79567.91 | AB11: 79567.91 | AC11: 79567.91 | AD11: 79567.91 | AE11: 79567.91 | AF11: 79567.91 | AG11: 79567.91 | AH11: 79567.91 | AI11: 79567.91 | AJ11: 79567.91 | AK11: 79567.91 | AL11: 79567.91
A12: BIY|FRANCES|USD|CC | B12: BIY | C12: FRANCES | D12: USD | E12: CC | F12: 2) DOLARES | G12: =IFERROR(INDEX(H12:AL12,MATCH(Resumen!$E$1,H$1:AL$1,0)),0) | H12: 476.6 | I12: 476.6 | J12: 476.6 | K12: 476.6 | L12: 476.6 | M12: 476.6 | N12: 476.6 | O12: 476.6 | P12: 476.6 | Q12: 476.6 | R12: 476.6 | S12: 476.6 | T12: 476.6 | U12: 476.6 | V12: 476.6 | W12: 476.6 | X12: 476.6 | Y12: 476.6 | Z12: 476.6 | AA12: 476.6 | AB12: 476.6 | AC12: 476.6 | AD12: 476.6 | AE12: 476.6 | AF12: 476.6 | AG12: 476.6 | AH12: 476.6 | AI12: 476.6 | AJ12: 476.6 | AK12: 476.6 | AL12: 476.6
A13: BIY|FRANCES|EUR|CC | B13: BIY | C13: FRANCES | D13: EUR | E13: CC | F13: 3) EUROS | G13: =IFERROR(INDEX(H13:AL13,MATCH(Resumen!$E$1,H$1:AL$1,0)),0) | H13: 0 | I13: 0 | J13: 0 | K13: 0 | L13: 0 | M13: 0 | N13: 0 | O13: 0 | P13: 0 | Q13: 0 | R13: 0 | S13: 0 | T13: 0 | U13: 0 | V13: 0 | W13: 0 | X13: 0 | Y13: 0 | Z13: 0 | AA13: 0 | AB13: 0 | AC13: 0 | AD13: 0 | AE13: 0 | AF13: 0 | AG13: 0 | AH13: 0 | AI13: 0 | AJ13: 0 | AK13: 0 | AL13: 0
... A34: BIY|TESORERIA|EUR|CC | B34: BIY | C34: TESORERIA | D34: EUR | E34: CC | F34: 3) EUROS | G34: =IFERROR(INDEX(H34:AL34,MATCH(Resumen!$E$1,H$1:AL$1,0)),0) | H34: 0 | I34: 0 | J34: 0 | K34: 0 | L34: 0 | M34: 0 | N34: 0 | O34: 0 | P34: 0 | Q34: 0 | R34: 0 | S34: 0 | T34: 0 | U34: 0 | V34: 0 | W34: 0 | X34: 0 | Y34: 0 | Z34: 0 | AA34: 0 | AB34: 0 | AC34: 0 | AD34: 0 | AE34: 0 | AF34: 0 | AG34: 0 | AH34: 0 | AI34: 0 | AJ34: 0 | AK34: 0 | AL34: 0
A35: BIY|INVERSIONES|ARS|FCI_GOAL_RENTA_GLOBAL | B35: BIY | C35: INVERSIONES | D35: ARS | F35: FCI Goal renta global | G35: =IFERROR(INDEX(H35:AL35,MATCH(Resumen!$E$1,H$1:AL$1,0)),0) | H35: 0 | I35: 0 | J35: 0 | K35: 0 | L35: 0 | M35: 0 | N35: 0 | O35: 0 | P35: 0 | Q35: 0 | R35: 0 | S35: 0 | T35: 0 | U35: 0 | V35: 0 | W35: 0 | X35: 0 | Y35: 0 | Z35: 0 | AA35: 0 | AB35: 0 | AC35: 0 | AD35: 0 | AE35: 0 | AF35: 0 | AG35: 0 | AH35: 0 | AI35: 0 | AJ35: 0 | AK35: 0 | AL35: 0
A36: BIY|INVERSIONES|ARS|FCI_PIONERO_RENTA_AHORRO | B36: BIY | C36: INVERSIONES | D36: ARS | F36: FCI Pionero Renta Ahorro | G36: =IFERROR(INDEX(H36:AL36,MATCH(Resumen!$E$1,H$1:AL$1,0)),0) | H36: 0 | I36: 0 | J36: 0 | K36: 0 | L36: 0 | M36: 0 | N36: 0 | O36: 0 | P36: 0 | Q36: 0 | R36: 0 | S36: 0 | T36: 0 | U36: 0 | V36: 0 | W36: 0 | X36: 0 | Y36: 0 | Z36: 0 | AA36: 0 | AB36: 0 | AC36: 0 | AD36: 0 | AE36: 0 | AF36: 0 | AG36: 0 | AH36: 0 | AI36: 0 | AJ36: 0 | AK36: 0 | AL36: 0
A37: BIY|INVERSIONES|ARS|FCI_RENTA_CRECIMIENTO | B37: BIY | C37: INVERSIONES | D37: ARS | F37: FCI renta crecimiento | G37: =IFERROR(INDEX(H37:AL37,MATCH(Resumen!$E$1,H$1:AL$1,0)),0) | H37: 0 | I37: 0 | J37: 0 | K37: 0 | L37: 0 | M37: 0 | N37: 0 | O37: 0 | P37: 0 | Q37: 0 | R37: 0 | S37: 0 | T37: 0 | U37: 0 | V37: 0 | W37: 0 | X37: 0 | Y37: 0 | Z37: 0 | AA37: 0 | AB37: 0 | AC37: 0 | AD37: 0 | AE37: 0 | AF37: 0 | AG37: 0 | AH37: 0 | AI37: 0 | AJ37: 0 | AK37: 0 | AL37: 0
A38: BIY|INVERSIONES|ARS|FCI_GOAL_PESOS | B38: BIY | C38: INVERSIONES | D38: ARS | F38: FCI Goal Pesos | G38: =IFERROR(INDEX(H38:AL38,MATCH(Resumen!$E$1,H$1:AL$1,0)),0) | H38: 0 | I38: 0 | J38: 0 | K38: 0 | L38: 0 | M38: 0 | N38: 0 | O38: 0 | P38: 0 | Q38: 0 | R38: 0 | S38: 0 | T38: 0 | U38: 0 | V38: 0 | W38: 0 | X38: 0 | Y38: 0 | Z38: 0 | AA38: 0 | AB38: 0 | AC38: 0 | AD38: 0 | AE38: 0 | AF38: 0 | AG38: 0 | AH38: 0 | AI38: 0 | AJ38: 0 | AK38: 0 | AL38: 0
A39: BIY|INVERSIONES|ARS|FCI_ACCIONES_ARGENTINAS | B39: BIY | C39: INVERSIONES | D39: ARS | F39: FCI acciones argentinas | G39: =IFERROR(INDEX(H39:AL39,MATCH(Resumen!$E$1,H$1:AL$1,0)),0) | H39: 0 | I39: 0 | J39: 0 | K39: 0 | L39: 0 | M39: 0 | N39: 0 | O39: 0 | P39: 0 | Q39: 0 | R39: 0 | S39: 0 | T39: 0 | U39: 0 | V39: 0 | W39: 0 | X39: 0 | Y39: 0 | Z39: 0 | AA39: 0 | AB39: 0 | AC39: 0 | AD39: 0 | AE39: 0 | AF39: 0 | AG39: 0 | AH39: 0 | AI39: 0 | AJ39: 0 | AK39: 0 | AL39: 0
A40: BIY|INVERSIONES|ARS|IAM_AHORRO_PESOS | B40: BIY | C40: INVERSIONES | D40: ARS | F40: IAM Ahorro Pesos | G40: =IFERROR(INDEX(H40:AL40,MATCH(Resumen!$E$1,H$1:AL$1,0)),0) | H40: 0 | I40: 0 | J40: 0 | K40: 0 | L40: 0 | M40: 0 | N40: 0 | O40: 0 | P40: 0 | Q40: 0 | R40: 0 | S40: 0 | T40: 0 | U40: 0 | V40: 0 | W40: 0 | X40: 0 | Y40: 0 | Z40: 0 | AA40: 0 | AB40: 0 | AC40: 0 | AD40: 0 | AE40: 0 | AF40: 0 | AG40: 0 | AH40: 0 | AI40: 0 | AJ40: 0 | AK40: 0 | AL40: 0
A41: BIY|INVERSIONES|ARS|PLAZO_FIJO | B41: BIY | C41: INVERSIONES | D41: ARS | F41: Plazo Fijo | G41: =IFERROR(INDEX(H41:AL41,MATCH(Resumen!$E$1,H$1:AL$1,0)),0) | H41: 0 | I41: 0 | J41: 0 | K41: 0 | L41: 0 | M41: 0 | N41: 0 | O41: 0 | P41: 0 | Q41: 0 | R41: 0 | S41: 0 | T41: 0 | U41: 0 | V41: 0 | W41: 0 | X41: 0 | Y41: 0 | Z41: 0 | AA41: 0 | AB41: 0 | AC41: 0 | AD41: 0 | AE41: 0 | AF41: 0 | AG41: 0 | AH41: 0 | AI41: 0 | AJ41: 0 | AK41: 0 | AL41: 0
A42: BIY|INVERSIONES|ARS|OTROS | B42: BIY | C42: INVERSIONES | D42: ARS | F42: Otros | G42: =IFERROR(INDEX(H42:AL42,MATCH(Resumen!$E$1,H$1:AL$1,0)),0) | H42: 0 | I42: 0 | J42: 0 | K42: 0 | L42: 0 | M42: 0 | N42: 0 | O42: 0 | P42: 0 | Q42: 0 | R42: 0 | S42: 0 | T42: 0 | U42: 0 | V42: 0 | W42: 0 | X42: 0 | Y42: 0 | Z42: 0 | AA42: 0 | AB42: 0 | AC42: 0 | AD42: 0 | AE42: 0 | AF42: 0 | AG42: 0 | AH42: 0 | AI42: 0 | AJ42: 0 | AK42: 0 | AL42: 0
A43: KAN|MACRO|ARS|CC | B43: KAN | C43: MACRO | D43: ARS | E43: CC | F43: 1) PESOS (CC) | G43: =IFERROR(INDEX(H43:AL43,MATCH(Resumen!$E$1,H$1:AL$1,0)),0) | H43: -4.0978534e+08 | I43: -4.0978534e+08 | J43: -4.7125205e+08 | K43: -4.8442293e+08 | L43: -38771053 | M43: -14805486 | N43: -38889286 | O43: -38889286 | P43: -38889286 | Q43: -10300879 | R43: -67393815 | S43: -95294984 | T43: -68874455 | U43: -68932591 | V43: -68932591 | W43: -68932591 | X43: -1.2251235e+08 | Y43: -1.2251235e+08 | Z43: -1.1132271e+08 | AA43: -85196304 | AB43: -91057789 | AC43: -91057789 | AD43: -91057789 | AE43: -67610525 | AF43: -65042181 | AG43: -69152932 | AH43: -49990179 | AI43: -40070217 | AJ43: -40070217 | AK43: -40070217 | AL43: -23426881
A44: KAN|MACRO|ARS|TRANSITO | B44: KAN | C44: MACRO | D44: ARS | E44: TRANSITO | F44: Depósitos en Tránsito | G44: =IFERROR(INDEX(H44:AL44,MATCH(Resumen!$E$1,H$1:AL$1,0)),0) | H44: 0 | I44: 0 | J44: 0 | K44: 0 | L44: 0 | M44: 0 | N44: 0 | O44: 0 | P44: 0 | Q44: 0 | R44: 0 | S44: 0 | T44: 0 | U44: 0 | V44: 0 | W44: 0 | X44: 0 | Y44: 0 | Z44: 0 | AA44: 0 | AB44: 0 | AC44: 0 | AD44: 0 | AE44: 0 | AF44: 0 | AG44: 0 | AH44: 0 | AI44: 0 | AJ44: 0 | AK44: 0 | AL44: 0
A45: KAN|MACRO|ARS|CA | B45: KAN | C45: MACRO | D45: ARS | E45: CA | F45: 1) PESOS (CA) | G45: =IFERROR(INDEX(H45:AL45,MATCH(Resumen!$E$1,H$1:AL$1,0)),0) | H45: 0 | I45: 0 | J45: 0 | K45: 0 | L45: 0 | M45: 0 | N45: 0 | O45: 0 | P45: 0 | Q45: 0 | R45: 0 | S45: 0 | T45: 0 | U45: 0 | V45: 0 | W45: 0 | X45: 0 | Y45: 0 | Z45: 0 | AA45: 0 | AB45: 0 | AC45: 0 | AD45: 0 | AE45: 0 | AF45: 0 | AG45: 0 | AH45: 0 | AI45: 0 | AJ45: 0 | AK45: 0 | AL45: 0
A46: KAN|MACRO|USD|CC | B46: KAN | C46: MACRO | D46: USD | E46: CC | F46: 2) DOLARES (CC) | G46: =IFERROR(INDEX(H46:AL46,MATCH(Resumen!$E$1,H$1:AL$1,0)),0) | H46: 64.09 | I46: 64.09 | J46: 64.09 | K46: 64.09 | L46: 64.09 | M46: 64.09 | N46: 64.09 | O46: 64.09 | P46: 64.09 | Q46: 64.09 | R46: 64.09 | S46: 64.09 | T46: 64.09 | U46: 64.09 | V46: 64.09 | W46: 64.09 | X46: 64.09 | Y46: 64.09 | Z46: 64.09 | AA46: 64.09 | AB46: 64.09 | AC46: 64.09 | AD46: 64.09 | AE46: 64.09 | AF46: 64.09 | AG46: 64.09 | AH46: 64.09 | AI46: 64.09 | AJ46: 64.09 | AK46: 64.09 | AL46: 34.08
A47: KAN|MACRO|USD|TRANSITO | B47: KAN | C47: MACRO | D47: USD | E47: TRANSITO | F47: Depósitos en Tránsito | G47: =IFERROR(INDEX(H47:AL47,MATCH(Resumen!$E$1,H$1:AL$1,0)),0) | H47: 0 | I47: 0 | J47: 0 | K47: 0 | L47: 0 | M47: 0 | N47: 0 | O47: 0 | P47: 0 | Q47: 0 | R47: 0 | S47: 0 | T47: 0 | U47: 0 | V47: 0 | W47: 0 | X47: 0 | Y47: 0 | Z47: 0 | AA47: 0 | AB47: 0 | AC47: 0 | AD47: 0 | AE47: 0 | AF47: 0 | AG47: 0 | AH47: 0 | AI47: 0 | AJ47: 0 | AK47: 0 | AL47: 0
A48: KAN|MACRO|USD|CA | B48: KAN | C48: MACRO | D48: USD | E48: CA | F48: 2) DOLARES (CA) | G48: =IFERROR(INDEX(H48:AL48,MATCH(Resumen!$E$1,H$1:AL$1,0)),0) | H48: 0 | I48: 0 | J48: 0 | K48: 0 | L48: 0 | M48: 0 | N48: 0 | O48: 0 | P48: 0 | Q48: 0 | R48: 0 | S48: 0 | T48: 0 | U48: 0 | V48: 0 | W48: 0 | X48: 0 | Y48: 0 | Z48: 0 | AA48: 0 | AB48: 0 | AC48: 0 | AD48: 0 | AE48: 0 | AF48: 0 | AG48: 0 | AH48: 0 | AI48: 0 | AJ48: 0 | AK48: 0 | AL48: 0
A49: KAN|ITAU|ARS|CC | B49: KAN | C49: ITAU | D49: ARS | E49: CC | F49: 1) PESOS (CC) | G49: =IFERROR(INDEX(H49:AL49,MATCH(Resumen!$E$1,H$1:AL$1,0)),0) | H49: 2030713.4 | I49: 2030713.4 | J49: 3069968.6 | K49: 1729472.1 | L49: -558345.32 | M49: 4183500.2 | N49: 1590039.8 | O49: 1590039.8 | P49: 1590039.8 | Q49: 2763317.2 | R49: 4919704.7 | S49: 5739254.9 | T49: 2720175.8 | U49: 3004048.9 | V49: 3004048.9 | W49: 3004048.9 | X49: 5049169.1 | Y49: 5049169.1 | Z49: 6264208.1 | AA49: 3484435 | AB49: 3687893.5 | AC49: 3687893.5 | AD49: 3687893.5 | AE49: 5472515.2 | AF49: 2346715.8 | AG49: 2758477 | AH49: 2787542.5 | AI49: 3078197.5 | AJ49: 3078197.5 | AK49: 3078197.5 | AL49: 7524584.5
A50: KAN|ITAU|ARS|TRANSITO | B50: KAN | C50: ITAU | D50: ARS | E50: TRANSITO | F50: Depósitos en Tránsito | G50: =IFERROR(INDEX(H50:AL50,MATCH(Resumen!$E$1,H$1:AL$1,0)),0) | H50: 0 | I50: 0 | J50: 0 | K50: 0 | L50: 0 | M50: 0 | N50: 0 | O50: 0 | P50: 0 | Q50: 0 | R50: 0 | S50: 0 | T50: 0 | U50: 0 | V50: 0 | W50: 0 | X50: 0 | Y50: 0 | Z50: 0 | AA50: 0 | AB50: 0 | AC50: 0 | AD50: 0 | AE50: 0 | AF50: 0 | AG50: 0 | AH50: 0 | AI50: 0 | AJ50: 0 | AK50: 0 | AL50: 0
A51: KAN|ITAU|ARS|AVELLANEDA | B51: KAN | C51: ITAU | D51: ARS | E51: AVELLANEDA | F51: 1) PESOS (AVELLANEDA) | G51: =IFERROR(INDEX(H51:AL51,MATCH(Resumen!$E$1,H$1:AL$1,0)),0) | H51: 0 | I51: 0 | J51: 0 | K51: 0 | L51: 0 | M51: 0 | N51: 0 | O51: 0 | P51: 0 | Q51: 0 | R51: 0 | S51: 0 | T51: 0 | U51: 0 | V51: 0 | W51: 0 | X51: 0 | Y51: 0 | Z51: 0 | AA51: 0 | AB51: 0 | AC51: 0 | AD51: 0 | AE51: 0 | AF51: 0 | AG51: 0 | AH51: 0 | AI51: 0 | AJ51: 0 | AK51: 0 | AL51: 0
A52: KAN|ITAU|USD|CC | B52: KAN | C52: ITAU | D52: USD | E52: CC | F52: 2) DOLARES (CC) | G52: =IFERROR(INDEX(H52:AL52,MATCH(Resumen!$E$1,H$1:AL$1,0)),0) | H52: 0 | I52: 0 | J52: 0 | K52: 0 | L52: 0 | M52: 0 | N52: 0 | O52: 0 | P52: 0 | Q52: 0 | R52: 0 | S52: 0 | T52: 0 | U52: 0 | V52: 0 | W52: 0 | X52: 0 | Y52: 0 | Z52: 0 | AA52: 0 | AB52: 0 | AC52: 0 | AD52: 0 | AE52: 0 | AF52: 0 | AG52: 0 | AH52: 0 | AI52: 0 | AJ52: 0 | AK52: 0 | AL52: 0
A53: KAN|ITAU|USD|TRANSITO | B53: KAN | C53: ITAU | D53: USD | E53: TRANSITO | F53: Depósitos en Tránsito | G53: =IFERROR(INDEX(H53:AL53,MATCH(Resumen!$E$1,H$1:AL$1,0)),0) | H53: 0 | I53: 0 | J53: 0 | K53: 0 | L53: 0 | M53: 0 | N53: 0 | O53: 0 | P53: 0 | Q53: 0 | R53: 0 | S53: 0 | T53: 0 | U53: 0 | V53: 0 | W53: 0 | X53: 0 | Y53: 0 | Z53: 0 | AA53: 0 | AB53: 0 | AC53: 0 | AD53: 0 | AE53: 0 | AF53: 0 | AG53: 0 | AH53: 0 | AI53: 0 | AJ53: 0 | AK53: 0 | AL53: 0
A54: KAN|FRANCES|ARS|CC | B54: KAN | C54: FRANCES | D54: ARS | E54: CC | F54: 1) PESOS | G54: =IFERROR(INDEX(H54:AL54,MATCH(Resumen!$E$1,H$1:AL$1,0)),0) | H54: 310946.67 | I54: 310946.67 | J54: 320794.54 | K54: 182267.67 | L54: 181436.88 | M54: 295784.12 | N54: 295098.06 | O54: 295098.06 | P54: 295098.06 | Q54: 295098.06 | R54: 295098.06 | S54: 295098.06 | T54: 295098.06 | U54: 295098.06 | V54: 295098.06 | W54: 295098.06 | X54: 295098.06 | Y54: 295098.06 | Z54: 295098.06 | AA54: 295098.06 | AB54: 295098.06 | AC54: 295098.06 | AD54: 295098.06 | AE54: 295098.06 | AF54: 295098.06 | AG54: 295098.06 | AH54: 295098.06 | AI54: 295098.06 | AJ54: 295098.06 | AK54: 295098.06 | AL54: 295098.06
... A77: KAN|TESORERIA|EUR|CC | B77: KAN | C77: TESORERIA | D77: EUR | E77: CC | F77: 3) EUROS | G77: =IFERROR(INDEX(H77:AL77,MATCH(Resumen!$E$1,H$1:AL$1,0)),0) | H77: 0 | I77: 0 | J77: 0 | K77: 0 | L77: 0 | M77: 0 | N77: 0 | O77: 0 | P77: 0 | Q77: 0 | R77: 0 | S77: 0 | T77: 0 | U77: 0 | V77: 0 | W77: 0 | X77: 0 | Y77: 0 | Z77: 0 | AA77: 0 | AB77: 0 | AC77: 0 | AD77: 0 | AE77: 0 | AF77: 0 | AG77: 0 | AH77: 0 | AI77: 0 | AJ77: 0 | AK77: 0 | AL77: 0
A78: KAN|INVERSIONES|ARS|FCI_PIONERO_PESOS | B78: KAN | C78: INVERSIONES | D78: ARS | F78: FCI Pionero Pesos | G78: =IFERROR(INDEX(H78:AL78,MATCH(Resumen!$E$1,H$1:AL$1,0)),0) | H78: 0 | I78: 0 | J78: 0 | K78: 0 | L78: 0 | M78: 0 | N78: 0 | O78: 0 | P78: 0 | Q78: 0 | R78: 0 | S78: 0 | T78: 0 | U78: 0 | V78: 0 | W78: 0 | X78: 0 | Y78: 0 | Z78: 0 | AA78: 0 | AB78: 0 | AC78: 0 | AD78: 0 | AE78: 0 | AF78: 0 | AG78: 0 | AH78: 0 | AI78: 0 | AJ78: 0 | AK78: 0 | AL78: 0
A79: KAN|INVERSIONES|ARS|FCI_PIONERO_RENTA_AHORRO | B79: KAN | C79: INVERSIONES | D79: ARS | F79: FCI Pionero Renta Ahorro | G79: =IFERROR(INDEX(H79:AL79,MATCH(Resumen!$E$1,H$1:AL$1,0)),0) | H79: 0 | I79: 0 | J79: 0 | K79: 0 | L79: 0 | M79: 0 | N79: 0 | O79: 0 | P79: 0 | Q79: 0 | R79: 0 | S79: 0 | T79: 0 | U79: 0 | V79: 0 | W79: 0 | X79: 0 | Y79: 0 | Z79: 0 | AA79: 0 | AB79: 0 | AC79: 0 | AD79: 0 | AE79: 0 | AF79: 0 | AG79: 0 | AH79: 0 | AI79: 0 | AJ79: 0 | AK79: 0 | AL79: 0
A80: KAN|INVERSIONES|ARS|FCI_PELLEGRINI_RENTA_PESOS | B80: KAN | C80: INVERSIONES | D80: ARS | F80: FCI Pellegrini Renta Pesos | G80: =IFERROR(INDEX(H80:AL80,MATCH(Resumen!$E$1,H$1:AL$1,0)),0) | H80: 0 | I80: 0 | J80: 0 | K80: 0 | L80: 0 | M80: 0 | N80: 0 | O80: 0 | P80: 0 | Q80: 0 | R80: 0 | S80: 0 | T80: 0 | U80: 0 | V80: 0 | W80: 0 | X80: 0 | Y80: 0 | Z80: 0 | AA80: 0 | AB80: 0 | AC80: 0 | AD80: 0 | AE80: 0 | AF80: 0 | AG80: 0 | AH80: 0 | AI80: 0 | AJ80: 0 | AK80: 0 | AL80: 0
A81: KAN|INVERSIONES|ARS|FCI_GOAL_PESOS | B81: KAN | C81: INVERSIONES | D81: ARS | F81: FCI Goal Pesos | G81: =IFERROR(INDEX(H81:AL81,MATCH(Resumen!$E$1,H$1:AL$1,0)),0) | H81: 0 | I81: 0 | J81: 0 | K81: 0 | L81: 0 | M81: 0 | N81: 0 | O81: 0 | P81: 0 | Q81: 0 | R81: 0 | S81: 0 | T81: 0 | U81: 0 | V81: 0 | W81: 0 | X81: 0 | Y81: 0 | Z81: 0 | AA81: 0 | AB81: 0 | AC81: 0 | AD81: 0 | AE81: 0 | AF81: 0 | AG81: 0 | AH81: 0 | AI81: 0 | AJ81: 0 | AK81: 0 | AL81: 0
A82: KAN|INVERSIONES|ARS|FCI_GOAL_CAPITAL_PLUS | B82: KAN | C82: INVERSIONES | D82: ARS | F82: FCI Goal Capital Plus | G82: =IFERROR(INDEX(H82:AL82,MATCH(Resumen!$E$1,H$1:AL$1,0)),0) | H82: 0 | I82: 0 | J82: 0 | K82: 0 | L82: 0 | M82: 0 | N82: 0 | O82: 0 | P82: 0 | Q82: 0 | R82: 0 | S82: 0 | T82: 0 | U82: 0 | V82: 0 | W82: 0 | X82: 0 | Y82: 0 | Z82: 0 | AA82: 0 | AB82: 0 | AC82: 0 | AD82: 0 | AE82: 0 | AF82: 0 | AG82: 0 | AH82: 0 | AI82: 0 | AJ82: 0 | AK82: 0 | AL82: 0
...

Sheet Resumen
A1: RESUMEN POSICIONES BANCARIAS Y TESORERIA | D1: Fecha | E1: 46265
A3: 1) Posiciones por Moneda
A5: PESOS | B5: Biyemas | C5: Kandiko | D5: Rebisco | E5: Total | G5: Biyemas Skill ON NET UT
A6: Banco Macro | B6: =SUMIF(Saldos!$A:$A,"BIY|MACRO|ARS|CC",Saldos!$G:$G)+SUMIF(Saldos!$A:$A,"BIY|MACRO|ARS|TRANSITO",Saldos!$G:$G) | C6: =SUMIF(Saldos!$A:$A,"KAN|MACRO|ARS|CC",Saldos!$G:$G)+SUMIF(Saldos!$A:$A,"KAN|MACRO|ARS|TRANSITO",Saldos!$G:$G)+SUMIF(Saldos!$A:$A,"KAN|MACRO|ARS|CA",Saldos!$G:$G) | D6: =SUMIF(Saldos!$A:$A,"REB|MACRO|ARS|CC",Saldos!$G:$G)+SUMIF(Saldos!$A:$A,"REB|MACRO|ARS|TRANSITO",Saldos!$G:$G)+SUMIF(Saldos!$A:$A,"REB|MACRO|ARS|CA",Saldos!$G:$G) | E6: =SUM(B6:D6) | G6: =SUMIF(Saldos!$A:$A,"UT|MACRO|ARS|CC",Saldos!$G:$G)
A7: Banco ITAU | B7: =SUMIF(Saldos!$A:$A,"BIY|ITAU|ARS|CC",Saldos!$G:$G)+SUMIF(Saldos!$A:$A,"BIY|ITAU|ARS|TRANSITO",Saldos!$G:$G)+SUMIF(Saldos!$A:$A,"BIY|ITAU|ARS|AVELLANEDA",Saldos!$G:$G) | C7: =SUMIF(Saldos!$A:$A,"KAN|ITAU|ARS|CC",Saldos!$G:$G) | D7: =SUMIF(Saldos!$A:$A,"REB|ITAU|ARS|CC",Saldos!$G:$G)+SUMIF(Saldos!$A:$A,"REB|ITAU|ARS|TRANSITO",Saldos!$G:$G)+SUMIF(Saldos!$A:$A,"REB|ITAU|ARS|AVELLANEDA",Saldos!$G:$G) | E7: =SUM(B7:D7) | G7: 0
A8: Banco Francés | B8: =SUMIF(Saldos!$A:$A,"BIY|FRANCES|ARS|CC",Saldos!$G:$G) | C8: =SUMIF(Saldos!$A:$A,"KAN|FRANCES|ARS|CC",Saldos!$G:$G) | D8: =SUMIF(Saldos!$A:$A,"REB|FRANCES|ARS|CC",Saldos!$G:$G) | E8: =SUM(B8:D8)
A9: Banco Provincia | B9: =SUMIF(Saldos!$A:$A,"BIY|BAPRO|ARS|CC",Saldos!$G:$G)+SUMIF(Saldos!$A:$A,"BIY|BAPRO|ARS|TRANSITO",Saldos!$G:$G) | C9: =SUMIF(Saldos!$A:$A,"KAN|BAPRO|ARS|CC",Saldos!$G:$G)+SUMIF(Saldos!$A:$A,"KAN|BAPRO|ARS|TRANSITO",Saldos!$G:$G) | D9: =SUMIF(Saldos!$A:$A,"REB|BAPRO|ARS|CC",Saldos!$G:$G)+SUMIF(Saldos!$A:$A,"REB|BAPRO|ARS|TRANSITO",Saldos!$G:$G) | E9: =SUM(B9:D9)
A10: BNA | B10: =SUMIF(Saldos!$A:$A,"BIY|BNA|ARS|CC",Saldos!$G:$G)+SUMIF(Saldos!$A:$A,"BIY|BNA|ARS|TRANSITO",Saldos!$G:$G) | C10: =SUMIF(Saldos!$A:$A,"KAN|BNA|ARS|CC",Saldos!$G:$G)+SUMIF(Saldos!$A:$A,"KAN|BNA|ARS|TRANSITO",Saldos!$G:$G) | D10: =SUMIF(Saldos!$A:$A,"REB|BNA|ARS|CC",Saldos!$G:$G)+SUMIF(Saldos!$A:$A,"REB|BNA|ARS|TRANSITO",Saldos!$G:$G) | E10: =SUM(B10:D10)
A11: Bi Bank | B11: =SUMIF(Saldos!$A:$A,"BIY|BIBANK|ARS|CC",Saldos!$G:$G)+SUMIF(Saldos!$A:$A,"BIY|BIBANK|ARS|TRANSITO",Saldos!$G:$G) | C11: =SUMIF(Saldos!$A:$A,"KAN|BIBANK|ARS|CC",Saldos!$G:$G)+SUMIF(Saldos!$A:$A,"KAN|BIBANK|ARS|TRANSITO",Saldos!$G:$G) | D11: =SUMIF(Saldos!$A:$A,"REB|BIBANK|ARS|CC",Saldos!$G:$G)+SUMIF(Saldos!$A:$A,"REB|BIBANK|ARS|TRANSITO",Saldos!$G:$G) | E11: =SUM(B11:D11)
A12: Banco Industrial | B12: =SUMIF(Saldos!$A:$A,"BIY|BIND|ARS|CC",Saldos!$G:$G)+SUMIF(Saldos!$A:$A,"BIY|BIND|ARS|TRANSITO",Saldos!$G:$G) | C12: =SUMIF(Saldos!$A:$A,"KAN|BIND|ARS|CC",Saldos!$G:$G)+SUMIF(Saldos!$A:$A,"KAN|BIND|ARS|TRANSITO",Saldos!$G:$G) | D12: =SUMIF(Saldos!$A:$A,"REB|BIND|ARS|CC",Saldos!$G:$G)+SUMIF(Saldos!$A:$A,"REB|BIND|ARS|TRANSITO",Saldos!$G:$G) | E12: =SUM(B12:D12)
A13: Maco | B13: =SUMIF(Saldos!$A:$A,"BIY|MACO|ARS|CC",Saldos!$G:$G) | C13: =SUMIF(Saldos!$A:$A,"KAN|MACO|ARS|CC",Saldos!$G:$G) | D13: =SUMIF(Saldos!$A:$A,"REB|MACO|ARS|CC",Saldos!$G:$G) | E13: =SUM(B13:D13)
A14: Banco Ciudad | B14: 0 | C14: 0 | D14: 0 | E14: =SUM(B14:D14) | G14: =SUMIF(Saldos!$A:$A,"UT|CIUDAD|ARS|CC",Saldos!$G:$G)+SUMIF(Saldos!$A:$A,"UT|CIUDAD|ARS|LOTBA",Saldos!$G:$G)
A15: Mercado Pago | B15: =SUMIF(Saldos!$A:$A,"BIY|MP|ARS|SALDO",Saldos!$G:$G) | C15: =SUMIF(Saldos!$A:$A,"KAN|MP|ARS|SALDO",Saldos!$G:$G) | D15: =SUMIF(Saldos!$A:$A,"REB|MP|ARS|SALDO",Saldos!$G:$G) | E15: =SUM(B15:D15) | G15: =SUMIF(Saldos!$A:$A,"UT|MACRO|ARS|TRANSITO",Saldos!$G:$G)
A16: Tesorería | B16: =SUMIF(Saldos!$A:$A,"BIY|TESORERIA|ARS|CC",Saldos!$G:$G) | C16: =SUMIF(Saldos!$A:$A,"KAN|TESORERIA|ARS|CC",Saldos!$G:$G) | D16: =SUMIF(Saldos!$A:$A,"REB|TESORERIA|ARS|CC",Saldos!$G:$G) | E16: =SUM(B16:D16)
A17: Total | B17: =SUM(B6:B16) | C17: =SUM(C6:C16) | D17: =SUM(D6:D16) | E17: =SUM(E6:E16) | G17: =SUM(G6:G16)
A19: DOLARES | B19: Biyemas | C19: Kandiko | D19: Rebisco | E19: Total | G19: Biyemas Skill ON NET UT
A20: Banco Macro | B20: =SUMIF(Saldos!$A:$A,"BIY|MACRO|USD|CC",Saldos!$G:$G) | C20: =SUMIF(Saldos!$A:$A,"KAN|MACRO|USD|CC",Saldos!$G:$G) | D20: =SUMIF(Saldos!$A:$A,"REB|MACRO|USD|CC",Saldos!$G:$G) | E20: =SUM(B20:D20) | G20: 0
A21: Banco ITAU | B21: =SUMIF(Saldos!$A:$A,"BIY|ITAU|USD|CC",Saldos!$G:$G) | C21: =SUMIF(Saldos!$A:$A,"KAN|ITAU|USD|CC",Saldos!$G:$G) | D21: =SUMIF(Saldos!$A:$A,"REB|ITAU|USD|CC",Saldos!$G:$G) | E21: =SUM(B21:D21) | G21: 0
A22: Banco Francés | B22: =SUMIF(Saldos!$A:$A,"BIY|FRANCES|USD|CC",Saldos!$G:$G) | C22: =SUMIF(Saldos!$A:$A,"KAN|FRANCES|USD|CC",Saldos!$G:$G) | D22: =SUMIF(Saldos!$A:$A,"REB|FRANCES|USD|CC",Saldos!$G:$G) | E22: =SUM(B22:D22) | G22: 0
A23: Banco Provincia | B23: =SUMIF(Saldos!$A:$A,"BIY|BAPRO|USD|CC",Saldos!$G:$G) | C23: =SUMIF(Saldos!$A:$A,"KAN|BAPRO|USD|CC",Saldos!$G:$G) | D23: =SUMIF(Saldos!$A:$A,"REB|BAPRO|USD|CC",Saldos!$G:$G) | E23: =SUM(B23:D23) | G23: 0
A24: BNA | B24: =SUMIF(Saldos!$A:$A,"BIY|BNA|USD|CC",Saldos!$G:$G) | C24: =SUMIF(Saldos!$A:$A,"KAN|BNA|USD|CC",Saldos!$G:$G) | D24: =SUMIF(Saldos!$A:$A,"REB|BNA|USD|CC",Saldos!$G:$G) | E24: =SUM(B24:D24) | G24: 0
A25: Bi Bank | B25: =SUMIF(Saldos!$A:$A,"BIY|BIBANK|USD|CC",Saldos!$G:$G) | C25: =SUMIF(Saldos!$A:$A,"KAN|BIBANK|USD|CC",Saldos!$G:$G) | D25: =SUMIF(Saldos!$A:$A,"REB|BIBANK|USD|CC",Saldos!$G:$G) | E25: =SUM(B25:D25) | G25: 0
A26: Banco Industrial | B26: =SUMIF(Saldos!$A:$A,"BIY|BIND|USD|CC",Saldos!$G:$G) | C26: =SUMIF(Saldos!$A:$A,"KAN|BIND|USD|CC",Saldos!$G:$G) | D26: =SUMIF(Saldos!$A:$A,"REB|BIND|USD|CC",Saldos!$G:$G) | E26: =SUM(B26:D26) | G26: 0
A27: Maco | B27: =SUMIF(Saldos!$A:$A,"BIY|MACO|USD|CC",Saldos!$G:$G) | C27: =SUMIF(Saldos!$A:$A,"KAN|MACO|USD|CC",Saldos!$G:$G) | D27: =SUMIF(Saldos!$A:$A,"REB|MACO|USD|CC",Saldos!$G:$G) | E27: =SUM(B27:D27) | G27: 0
A28: Tesorería | B28: =SUMIF(Saldos!$A:$A,"BIY|TESORERIA|USD|CC",Saldos!$G:$G) | C28: =SUMIF(Saldos!$A:$A,"KAN|TESORERIA|USD|CC",Saldos!$G:$G) | D28: =SUMIF(Saldos!$A:$A,"REB|TESORERIA|USD|CC",Saldos!$G:$G) | E28: =SUM(B28:D28) | G28: 0
A29: Total | B29: =SUM(B20:B28) | C29: =SUM(C20:C28) | D29: =SUM(D20:D28) | E29: =SUM(E20:E28) | G29: =SUM(G20:G28)
A31: EUROS | B31: Biyemas | C31: Kandiko | D31: Rebisco | E31: Total | G31: Biyemas Skill ON NET UT
A32: Banco Macro | B32: =SUMIF(Saldos!$A:$A,"BIY|MACRO|EUR|CC",Saldos!$G:$G) | C32: =SUMIF(Saldos!$A:$A,"KAN|MACRO|EUR|CC",Saldos!$G:$G) | D32: =SUMIF(Saldos!$A:$A,"REB|MACRO|EUR|CC",Saldos!$G:$G) | E32: =SUM(B32:D32) | G32: 0
A33: Banco Francés | B33: =SUMIF(Saldos!$A:$A,"BIY|FRANCES|EUR|CC",Saldos!$G:$G) | C33: =SUMIF(Saldos!$A:$A,"KAN|FRANCES|EUR|CC",Saldos!$G:$G) | D33: =SUMIF(Saldos!$A:$A,"REB|FRANCES|EUR|CC",Saldos!$G:$G) | E33: =SUM(B33:D33) | G33: 0
A34: Banco Provincia | B34: =SUMIF(Saldos!$A:$A,"BIY|BAPRO|EUR|CC",Saldos!$G:$G) | C34: =SUMIF(Saldos!$A:$A,"KAN|BAPRO|EUR|CC",Saldos!$G:$G) | D34: =SUMIF(Saldos!$A:$A,"REB|BAPRO|EUR|CC",Saldos!$G:$G) | E34: =SUM(B34:D34) | G34: 0
A35: Maco | B35: =SUMIF(Saldos!$A:$A,"BIY|MACO|EUR|CC",Saldos!$G:$G) | C35: =SUMIF(Saldos!$A:$A,"KAN|MACO|EUR|CC",Saldos!$G:$G) | D35: =SUMIF(Saldos!$A:$A,"REB|MACO|EUR|CC",Saldos!$G:$G) | E35: =SUM(B35:D35) | G35: 0
A36: Tesorería | B36: =SUMIF(Saldos!$A:$A,"BIY|TESORERIA|EUR|CC",Saldos!$G:$G) | C36: =SUMIF(Saldos!$A:$A,"KAN|TESORERIA|EUR|CC",Saldos!$G:$G) | D36: =SUMIF(Saldos!$A:$A,"REB|TESORERIA|EUR|CC",Saldos!$G:$G) | E36: =SUM(B36:D36) | G36: 0
A37: Total | B37: =SUM(B32:B36) | C37: =SUM(C32:C36) | D37: =SUM(D32:D36) | E37: =SUM(E32:E36) | G37: =SUM(G32:G36)
A39: 2) Posiciones Bancarias (Saldos Pesificados)
A41: Cotización Dólar Comprador: | B41: 1400
A42: Cotización Euro Comprador: | B42: 1500
A44: Banco | B44: Biyemas | C44: Kandiko | D44: Rebisco | E44: Total | G44: Biyemas Skill ON NET UT
A45: Macro (PESOS) | B45: =B6 | C45: =C6 | D45: =D6 | E45: =SUM(B45:D45) | G45: 0
A46: ITAU (PESOS) | B46: =B7 | C46: =C7 | D46: =D7 | E46: =SUM(B46:D46) | G46: 0
A47: Francés (PESOS) | B47: =B8 | C47: =C8 | D47: =D8 | E47: =SUM(B47:D47) | G47: 0
...

Sheet _MapaCodigos
A1: celda_resumen | B1: codigos | C1: nota
A2: B6 | B2: BIY|MACRO|ARS|CC + BIY|MACRO|ARS|TRANSITO
A3: C6 | B3: KAN|MACRO|ARS|CC + KAN|MACRO|ARS|TRANSITO + KAN|MACRO|ARS|CA
A4: D6 | B4: REB|MACRO|ARS|CC + REB|MACRO|ARS|TRANSITO + REB|MACRO|ARS|CA
A5: G6 | B5: UT|MACRO|ARS|CC
A6: B7 | B6: BIY|ITAU|ARS|CC + BIY|ITAU|ARS|TRANSITO + BIY|ITAU|ARS|AVELLANEDA
A7: C7 | B7: KAN|ITAU|ARS|CC
A8: D7 | B8: REB|ITAU|ARS|CC + REB|ITAU|ARS|TRANSITO + REB|ITAU|ARS|AVELLANEDA
A9: B8 | B9: BIY|FRANCES|ARS|CC
A10: C8 | B10: KAN|FRANCES|ARS|CC
A11: D8 | B11: REB|FRANCES|ARS|CC
A12: B9 | B12: BIY|BAPRO|ARS|CC + BIY|BAPRO|ARS|TRANSITO
A13: C9 | B13: KAN|BAPRO|ARS|CC + KAN|BAPRO|ARS|TRANSITO
... A44: B23 | B44: BIY|BAPRO|USD|CC
A45: C23 | B45: KAN|BAPRO|USD|CC | C45: FIX vs Excel viejo (antes fila 84 Francés EUR)
A46: D23 | B46: REB|BAPRO|USD|CC | C46: FIX vs Excel viejo (antes fila 135 Macro tránsito)
A47: B24 | B47: BIY|BNA|USD|CC
A48: C24 | B48: KAN|BNA|USD|CC
A49: D24 | B49: REB|BNA|USD|CC
A50: B25 | B50: BIY|BIBANK|USD|CC
A51: C25 | B51: KAN|BIBANK|USD|CC
A52: D25 | B52: REB|BIBANK|USD|CC
A53: B26 | B53: BIY|BIND|USD|CC
A54: C26 | B54: KAN|BIND|USD|CC
A55: D26 | B55: REB|BIND|USD|CC
A56: B27 | B56: BIY|MACO|USD|CC
A57: C27 | B57: KAN|MACO|USD|CC
A58: D27 | B58: REB|MACO|USD|CC
... A86: D73 | B86: REB|INVERSIONES|ARS|OTROS

Sheet _Instrucciones
A1: Cómo usar esta plantilla
A3: 1. Hoja Saldos = dato base. Pegar/importar saldos Interbanking en las columnas de fecha (desde H).
A4: 2. Cada fila tiene un codigo estable (col A). No insertar filas a mano sin mantener el codigo.
A5: 3. Columna G (saldo_dia) toma el valor de la fecha indicada en Resumen!E1.
A6: 4. Resumen no usa HLOOKUP por número de fila: usa SUMIF por codigo.
A7: 5. Completar cotizaciones en Resumen!B41 (USD) y B42 (EUR).
A8: 6. Cheques y hojas por banco se agregan en Fase 2/3.
A9: 7. Generado desde docs/tesoreria/posicion-bancaria-diaria/generar_plantilla_posicion.py
